<?xml version="1.0" ?>
<!-- =================================================================================== -->
<!-- |    This document was autogenerated by xacro from george.urdf.xacro              | -->
<!-- |    EDITING THIS FILE BY HAND IS NOT RECOMMENDED                                 | -->
<!-- =================================================================================== -->
<robot name="george" xmlns:xacro="http://www.ros.org/wiki/xacro">
  <!-- Import all Gazebo-customization elements, including Gazebo colors -->
  <gazebo>
    <plugin filename="libgazebo_ros_control.so" name="gazebo_ros_control">
      <robotNamespace>/george</robotNamespace>
    </plugin>
  </gazebo>
  <link name="torso_mass">
    <visual>
      <geometry>
        <box size=".001 .001 .001"/>
      </geometry>
    </visual>
    <collision>
      <geometry>
        <box size=".001 .001 .001"/>
      </geometry>
    </collision>
    <inertial>
      <inertia ixx="0.001" ixy="0.0" ixz="0.0" iyy="0.001" iyz="0.0" izz="0.001"/>
      <mass value="0.4"/>
    </inertial>
  </link>
  <link name="base_link">
    <visual>
      <geometry>
        <mesh filename="package://george/meshes/torso_mm.dae" scale="1 1 1"/>
      </geometry>
      <origin rpy="1.5708 0 3.1416" xyz="0 0 0"/>
      <material name="blue">
        <color rgba="0 0 .8 1"/>
      </material>
    </visual>
    <collision>
      <geometry>
        <box size=".040 .02 .0365"/>
      </geometry>
      <origin rpy="0 0 3.1416" xyz="0 0 0"/>
    </collision>
    <!--       <inertial>
	<mass value="0.001"/>
	<xacro:default_inertia/>
      </inertial>
-->
  </link>
  <!-- *****  Servo macro **********  -->
  <!-- servo body parent - for use when the body is the parent -->
  <!-- servo horn parent - for use when the body is the parent -->
  <!-- end servo macro -->
  <!-- cbracket macro, visual origin at inside end -->
  <!-- end multi purpose bracket -->
  <!-- multi purpose bracket macro A side as the parent -->
  <!-- multi purpose bracket macro B side as the parent -->
  <!-- multi purpose bracket macro C side as the parent -->
  <!-- multi purpose bracket macro C side as the parent, rotated -->
  <!-- multi purpose bracket macro -->
  <!-- end multi purpose bracket -->
  <!-- offset-c bracket macro -->
  <!-- end offset c bracket -->
  <!-- lconnector macro -->
  <!-- end lconnector -->
  <!-- foot macro -->
  <!-- end foot macro -->
  <!-- tube -->
  <!-- end tube -->
  <!-- gripper macro -->
  <!-- end gripper macro -->
  <!-- low profile axis macro -->
  <!-- end low profile axis macro -->
  <!-- *********************************************************** -->
  <!-- ****************************** Main robot definition ***************** -->
  <!-- *********************************************************** -->
  <!-- *********************************************************** -->
  <!-- ********* Left Leg **************************************** -->
  <!-- *********************************************************** -->
  <link name="LWaist_servo_body">
    <visual>
      <geometry>
        <box size=".040 .02 .0365"/>
      </geometry>
      <origin rpy="0 0 0" xyz="0 0 -0.00825"/>
      <material name="black">
        <color rgba=".1 .1 1 1"/>
      </material>
    </visual>
    <collision>
      <geometry>
        <box size=".040 .02 .0365"/>
      </geometry>
      <origin rpy="0 0 0" xyz="0 0 -0.00825"/>
    </collision>
    <inertial>
      <mass value="0.055"/>
      <inertia ixx="0.001" ixy="0.0" ixz="0.0" iyy="0.001" iyz="0.0" izz="0.001"/>
    </inertial>
  </link>
  <link name="LWaist_servo_lip">
    <visual>
      <geometry>
        <box size=".0528 .02 .002"/>
      </geometry>
      <origin rpy="0 0 0.001" xyz="0 0 0"/>
      <material name="black">
        <color rgba=".1 .1 1 1"/>
      </material>
    </visual>
    <collision>
      <geometry>
        <box size=".0528 .02 .002"/>
      </geometry>
      <origin rpy="0 0 0.001" xyz="0 0 0"/>
    </collision>
    <inertial>
      <mass value="0.001"/>
      <inertia ixx="0.001" ixy="0.0" ixz="0.0" iyy="0.001" iyz="0.0" izz="0.001"/>
    </inertial>
  </link>
  <link name="LWaist_servo_horn">
    <visual>
      <geometry>
        <cylinder length="0.001" radius="0.012"/>
      </geometry>
      <origin rpy="0 0 0" xyz="0 0 -.0005"/>
      <material name="white">
        <color rgba="1 1 1 1"/>
      </material>
    </visual>
    <collision>
      <geometry>
        <cylinder length="0.001" radius="0.012"/>
      </geometry>
      <origin rpy="0 0 0" xyz="0 0 -.0005"/>
    </collision>
    <inertial>
      <mass value="0.001"/>
      <inertia ixx="0.001" ixy="0.0" ixz="0.0" iyy="0.001" iyz="0.0" izz="0.001"/>
    </inertial>
  </link>
  <joint name="LWaist_servo_lip_to_body" type="fixed">
    <parent link="LWaist_servo_body"/>
    <child link="LWaist_servo_lip"/>
    <origin xyz="0 0 0"/>
  </joint>
  <joint name="LWaist" type="revolute">
    <axis xyz="0 0 -1"/>
    <limit effort="1000.0" lower="-1.5708" upper="1.5708" velocity="0.5"/>
    <parent link="LWaist_servo_body"/>
    <child link="LWaist_servo_horn"/>
    <origin rpy="0 0 1.5708" xyz=".01 0 0.0161"/>
  </joint>
  <joint name="torso_to_base" type="fixed">
    <parent link="base_link"/>
    <child link="torso_mass"/>
    <origin rpy="0 0 0" xyz="0 0 0"/>
  </joint>
  <joint name="torso_to_lwaist" type="fixed">
    <parent link="base_link"/>
    <child link="LWaist_servo_body"/>
    <origin rpy="1.5708 1.5708 0" xyz="0.032 0.005 0.03"/>
  </joint>
  <link name="lthigh1">
    <visual>
      <geometry>
        <mesh filename="package://george/meshes/cbracket-simple.dae" scale="1 1 1"/>
      </geometry>
      <origin rpy="0 1.5708 0" xyz="0 -0.0286 -0.0246"/>
      <material name="blue">
        <color rgba="0 0 .8 1"/>
      </material>
    </visual>
    <collision>
      <geometry>
        <box size=".005 .005 .005"/>
        <!--  mesh filename="package://george/meshes/cbracket-simple.dae" scale="1 1 1"/-->
      </geometry>
      <origin rpy="0 1.5708 0" xyz="0 -0.0286 -0.0246"/>
    </collision>
    <inertial>
      <mass value="0.001"/>
      <inertia ixx="0.001" ixy="0.0" ixz="0.0" iyy="0.001" iyz="0.0" izz="0.001"/>
    </inertial>
  </link>
  <joint name="lthigh1_to_lwaist" type="fixed">
    <parent link="LWaist_servo_horn"/>
    <child link="lthigh1"/>
    <origin rpy="0 0 0" xyz="0 0 0"/>
  </joint>
  <link name="lthigh2">
    <visual>
      <geometry>
        <mesh filename="package://george/meshes/multi-purp-simple.dae" scale="1 1 1"/>
      </geometry>
      <origin rpy="-1.5708 0 1.5708" xyz="0 0 0"/>
      <material name="blue">
        <color rgba="0 0 .8 1"/>
      </material>
    </visual>
    <collision>
      <geometry>
        <box size=".005 .005 .005"/>
        <!--  mesh filename="package://george/meshes/multi-purp-simple.dae" scale="1 1 1"/-->
      </geometry>
      <origin rpy="-1.5708 0 1.5708" xyz="0 0 0"/>
    </collision>
    <inertial>
      <mass value="0.001"/>
      <inertia ixx="0.001" ixy="0.0" ixz="0.0" iyy="0.001" iyz="0.0" izz="0.001"/>
    </inertial>
  </link>
  <joint name="lthigh1_to_lthigh2" type="fixed">
    <parent link="lthigh1"/>
    <child link="lthigh2"/>
    <origin rpy="-1.5708 0 0" xyz="-0.0054 -0.0286 -0.0329"/>
  </joint>
  <link name="LHip_servo_body">
    <visual>
      <geometry>
        <box size=".040 .02 .0365"/>
      </geometry>
      <origin rpy="0 0 0" xyz="0 0 -0.00825"/>
      <material name="black">
        <color rgba=".1 .1 1 1"/>
      </material>
    </visual>
    <collision>
      <geometry>
        <box size=".040 .02 .0365"/>
      </geometry>
      <origin rpy="0 0 0" xyz="0 0 -0.00825"/>
    </collision>
    <inertial>
      <mass value="0.055"/>
      <inertia ixx="0.001" ixy="0.0" ixz="0.0" iyy="0.001" iyz="0.0" izz="0.001"/>
    </inertial>
  </link>
  <link name="LHip_servo_lip">
    <visual>
      <geometry>
        <box size=".0528 .02 .002"/>
      </geometry>
      <origin rpy="0 0 0.001" xyz="0 0 0"/>
      <material name="black">
        <color rgba=".1 .1 1 1"/>
      </material>
    </visual>
    <collision>
      <geometry>
        <box size=".0528 .02 .002"/>
      </geometry>
      <origin rpy="0 0 0.001" xyz="0 0 0"/>
    </collision>
    <inertial>
      <mass value="0.001"/>
      <inertia ixx="0.001" ixy="0.0" ixz="0.0" iyy="0.001" iyz="0.0" izz="0.001"/>
    </inertial>
  </link>
  <link name="LHip_servo_horn">
    <visual>
      <geometry>
        <cylinder length="0.001" radius="0.012"/>
      </geometry>
      <origin rpy="0 0 0" xyz="0 0 -.0005"/>
      <material name="white">
        <color rgba="1 1 1 1"/>
      </material>
    </visual>
    <collision>
      <geometry>
        <cylinder length="0.001" radius="0.012"/>
      </geometry>
      <origin rpy="0 0 0" xyz="0 0 -.0005"/>
    </collision>
    <inertial>
      <mass value="0.001"/>
      <inertia ixx="0.001" ixy="0.0" ixz="0.0" iyy="0.001" iyz="0.0" izz="0.001"/>
    </inertial>
  </link>
  <joint name="LHip_servo_lip_to_body" type="fixed">
    <parent link="LHip_servo_body"/>
    <child link="LHip_servo_lip"/>
    <origin xyz="0 0 0"/>
  </joint>
  <joint name="LHip" type="revolute">
    <axis xyz="0 0 -1"/>
    <limit effort="1000.0" lower="-1.5708" upper="1.5708" velocity="0.5"/>
    <parent link="LHip_servo_body"/>
    <child link="LHip_servo_horn"/>
    <origin rpy="0 0 3.1416" xyz=".01 0 0.0161"/>
  </joint>
  <joint name="lthigh2_to_LHip" type="fixed">
    <parent link="lthigh2"/>
    <child link="LHip_servo_body"/>
    <origin rpy="-1.5708 0 -1.5708" xyz="0.0144 0 -0.0142"/>
  </joint>
  <link name="lthigh3">
    <visual>
      <geometry>
        <mesh filename="package://george/meshes/cbracket-simple.dae" scale="1 1 1"/>
      </geometry>
      <origin rpy="0 1.5708 0" xyz="0 -0.0286 -0.0246"/>
      <material name="blue">
        <color rgba="0 0 .8 1"/>
      </material>
    </visual>
    <collision>
      <geometry>
        <box size=".005 .005 .005"/>
        <!--  mesh filename="package://george/meshes/cbracket-simple.dae" scale="1 1 1"/-->
      </geometry>
      <origin rpy="0 1.5708 0" xyz="0 -0.0286 -0.0246"/>
    </collision>
    <inertial>
      <mass value="0.001"/>
      <inertia ixx="0.001" ixy="0.0" ixz="0.0" iyy="0.001" iyz="0.0" izz="0.001"/>
    </inertial>
  </link>
  <joint name="lthigh3_to_lhip" type="fixed">
    <parent link="LHip_servo_horn"/>
    <child link="lthigh3"/>
    <origin rpy="0 0 0" xyz="0 0 0"/>
  </joint>
  <link name="lthigh4">
    <visual>
      <geometry>
        <mesh filename="package://george/meshes/cbracket-simple.dae" scale="1 1 1"/>
      </geometry>
      <origin rpy="-1.5708 0 0" xyz="0 0 0"/>
      <material name="blue">
        <color rgba="0 0 .8 1"/>
      </material>
    </visual>
    <collision>
      <geometry>
        <box size=".005 .005 .005"/>
        <!--  mesh filename="package://george/meshes/cbracket-simple.dae" scale="1 1 1"/-->
      </geometry>
      <origin rpy="-1.5708 0 0" xyz="0 0 0"/>
    </collision>
    <inertial>
      <mass value="0.001"/>
      <inertia ixx="0.001" ixy="0.0" ixz="0.0" iyy="0.001" iyz="0.0" izz="0.001"/>
    </inertial>
  </link>
  <joint name="lthigh3_to_lthigh4" type="fixed">
    <parent link="lthigh3"/>
    <child link="lthigh4"/>
    <origin rpy="-1.5708 1.5708 0" xyz="0 -0.0286 -0.0246"/>
  </joint>
  <link name="LKnee_servo_body">
    <visual>
      <geometry>
        <box size=".040 .02 .0365"/>
      </geometry>
      <origin rpy="0 0 0" xyz="0.0161 0 -0.00825"/>
      <material name="black">
        <color rgba=".1 .1 1 1"/>
      </material>
    </visual>
    <collision>
      <geometry>
        <box size=".040 .02 .0365"/>
      </geometry>
      <origin rpy="0 0 0" xyz="0.0161 0 -0.00825"/>
    </collision>
    <inertial>
      <mass value="0.055"/>
      <inertia ixx="0.001" ixy="0.0" ixz="0.0" iyy="0.001" iyz="0.0" izz="0.001"/>
    </inertial>
  </link>
  <link name="LKnee_servo_lip">
    <visual>
      <geometry>
        <box size=".0528 .02 .002"/>
      </geometry>
      <origin rpy="0 0 0.001" xyz="0 0 0"/>
      <material name="black">
        <color rgba=".1 .1 1 1"/>
      </material>
    </visual>
    <collision>
      <geometry>
        <box size=".0528 .02 .002"/>
      </geometry>
      <origin rpy="0 0 0.001" xyz="0 0 0"/>
    </collision>
    <inertial>
      <mass value="0.001"/>
      <inertia ixx="0.001" ixy="0.0" ixz="0.0" iyy="0.001" iyz="0.0" izz="0.001"/>
    </inertial>
  </link>
  <link name="LKnee_servo_horn">
    <visual>
      <geometry>
        <cylinder length="0.001" radius="0.012"/>
      </geometry>
      <origin rpy="0 0 0" xyz="0 0 -.0005"/>
      <material name="white">
        <color rgba="1 1 1 1"/>
      </material>
    </visual>
    <collision>
      <geometry>
        <cylinder length="0.001" radius="0.012"/>
      </geometry>
      <origin rpy="0 0 0" xyz="0 0 -.0005"/>
    </collision>
    <inertial>
      <mass value="0.001"/>
      <inertia ixx="0.001" ixy="0.0" ixz="0.0" iyy="0.001" iyz="0.0" izz="0.001"/>
    </inertial>
  </link>
  <joint name="LKnee_servo_lip_to_body" type="fixed">
    <parent link="LKnee_servo_body"/>
    <child link="LKnee_servo_lip"/>
    <origin xyz="0.0161 0 0"/>
  </joint>
  <joint name="LKnee" type="revolute">
    <axis xyz="0 0 1"/>
    <limit effort="1000.0" lower="-1.5708" upper="1.5708" velocity="0.5"/>
    <parent link="LKnee_servo_horn"/>
    <child link="LKnee_servo_body"/>
    <origin rpy="0 0 1.5708" xyz="0.0 0 -0.0161"/>
  </joint>
  <joint name="lthigh4_to_lknee" type="fixed">
    <parent link="lthigh4"/>
    <child link="LKnee_servo_horn"/>
    <origin rpy="0 -1.5708 0" xyz="-0.0246 0 -0.0286"/>
  </joint>
  <link name="lknee1">
    <visual>
      <geometry>
        <mesh filename="package://george/meshes/multi-purp-simple.dae" scale="1 1 1"/>
      </geometry>
      <origin rpy="0 3.1416 3.1416" xyz="0.0161 0.0142 -0.0144"/>
      <material name="blue">
        <color rgba="0 0 .8 1"/>
      </material>
    </visual>
    <collision>
      <geometry>
        <box size=".005 .005 .005"/>
        <!--  mesh filename="package://george/meshes/multi-purp-simple.dae" scale="1 1 1"/-->
      </geometry>
      <origin rpy="0 3.1416 3.1416" xyz="0.0161 0.0142 -0.0144"/>
    </collision>
    <inertial>
      <mass value="0.001"/>
      <inertia ixx="0.001" ixy="0.0" ixz="0.0" iyy="0.001" iyz="0.0" izz="0.001"/>
    </inertial>
  </link>
  <joint name="lknee_to_lknee1" type="fixed">
    <parent link="LKnee_servo_body"/>
    <child link="lknee1"/>
    <origin rpy="0 0 0" xyz="0 0 0"/>
  </joint>
  <link name="lknee2">
    <visual>
      <geometry>
        <mesh filename="package://george/meshes/cbracket-simple.dae" scale="1 1 1"/>
      </geometry>
      <origin rpy="-1.5708 0 0" xyz="0 0 0"/>
      <material name="blue">
        <color rgba="0 0 .8 1"/>
      </material>
    </visual>
    <collision>
      <geometry>
        <box size=".005 .005 .005"/>
        <!--  mesh filename="package://george/meshes/cbracket-simple.dae" scale="1 1 1"/-->
      </geometry>
      <origin rpy="-1.5708 0 0" xyz="0 0 0"/>
    </collision>
    <inertial>
      <mass value="0.001"/>
      <inertia ixx="0.001" ixy="0.0" ixz="0.0" iyy="0.001" iyz="0.0" izz="0.001"/>
    </inertial>
  </link>
  <joint name="lknee1_to_lknee2" type="fixed">
    <parent link="lknee1"/>
    <child link="lknee2"/>
    <origin rpy="1.5708 1.5708 0" xyz="0.0078 0.0141 -0.008"/>
  </joint>
  <link name="LAnkleBend_servo_body">
    <visual>
      <geometry>
        <box size=".040 .02 .0365"/>
      </geometry>
      <origin rpy="0 0 0" xyz="0.0161 0 -0.00825"/>
      <material name="black">
        <color rgba=".1 .1 1 1"/>
      </material>
    </visual>
    <collision>
      <geometry>
        <box size=".040 .02 .0365"/>
      </geometry>
      <origin rpy="0 0 0" xyz="0.0161 0 -0.00825"/>
    </collision>
    <inertial>
      <mass value="0.055"/>
      <inertia ixx="0.001" ixy="0.0" ixz="0.0" iyy="0.001" iyz="0.0" izz="0.001"/>
    </inertial>
  </link>
  <link name="LAnkleBend_servo_lip">
    <visual>
      <geometry>
        <box size=".0528 .02 .002"/>
      </geometry>
      <origin rpy="0 0 0.001" xyz="0 0 0"/>
      <material name="black">
        <color rgba=".1 .1 1 1"/>
      </material>
    </visual>
    <collision>
      <geometry>
        <box size=".0528 .02 .002"/>
      </geometry>
      <origin rpy="0 0 0.001" xyz="0 0 0"/>
    </collision>
    <inertial>
      <mass value="0.001"/>
      <inertia ixx="0.001" ixy="0.0" ixz="0.0" iyy="0.001" iyz="0.0" izz="0.001"/>
    </inertial>
  </link>
  <link name="LAnkleBend_servo_horn">
    <visual>
      <geometry>
        <cylinder length="0.001" radius="0.012"/>
      </geometry>
      <origin rpy="0 0 0" xyz="0 0 -.0005"/>
      <material name="white">
        <color rgba="1 1 1 1"/>
      </material>
    </visual>
    <collision>
      <geometry>
        <cylinder length="0.001" radius="0.012"/>
      </geometry>
      <origin rpy="0 0 0" xyz="0 0 -.0005"/>
    </collision>
    <inertial>
      <mass value="0.001"/>
      <inertia ixx="0.001" ixy="0.0" ixz="0.0" iyy="0.001" iyz="0.0" izz="0.001"/>
    </inertial>
  </link>
  <joint name="LAnkleBend_servo_lip_to_body" type="fixed">
    <parent link="LAnkleBend_servo_body"/>
    <child link="LAnkleBend_servo_lip"/>
    <origin xyz="0.0161 0 0"/>
  </joint>
  <joint name="LAnkleBend" type="revolute">
    <axis xyz="0 0 1"/>
    <limit effort="1000.0" lower="-1.5708" upper="1.5708" velocity="0.5"/>
    <parent link="LAnkleBend_servo_horn"/>
    <child link="LAnkleBend_servo_body"/>
    <origin rpy="0 0 -1.5708" xyz="0.0 0 -0.0161"/>
  </joint>
  <joint name="lknee2_to_lanklebend" type="fixed">
    <parent link="lknee2"/>
    <child link="LAnkleBend_servo_horn"/>
    <origin rpy="0 -1.5708 0" xyz="-0.0246 0 -0.0286"/>
  </joint>
  <link name="lshin1">
    <visual>
      <geometry>
        <mesh filename="package://george/meshes/multi-purp-simple.dae" scale="1 1 1"/>
      </geometry>
      <origin rpy="0 3.1416 0" xyz="0.0161 -0.0142 -0.0144"/>
      <material name="blue">
        <color rgba="0 0 .8 1"/>
      </material>
    </visual>
    <collision>
      <geometry>
        <box size=".005 .005 .005"/>
        <!--  mesh filename="package://george/meshes/multi-purp-simple.dae" scale="1 1 1"/-->
      </geometry>
      <origin rpy="0 3.1416 0" xyz="0.0161 -0.0142 -0.0144"/>
    </collision>
    <inertial>
      <mass value="0.001"/>
      <inertia ixx="0.001" ixy="0.0" ixz="0.0" iyy="0.001" iyz="0.0" izz="0.001"/>
    </inertial>
  </link>
  <joint name="lanklebend_to_lshin1" type="fixed">
    <parent link="LAnkleBend_servo_body"/>
    <child link="lshin1"/>
    <origin rpy="0 0 0" xyz="0 0 0"/>
  </joint>
  <link name="lpleft">
    <visual>
      <geometry>
        <mesh filename="package://george/meshes/low-profile-simple.dae" scale="1 1 1"/>
      </geometry>
      <origin rpy="-1.5708 -1.5708 0" xyz="0 0 0"/>
      <material name="blue">
        <color rgba="0 0 .8 1"/>
      </material>
    </visual>
    <collision>
      <geometry>
        <box size=".005 .005 .005"/>
        <!--  mesh filename="package://george/meshes/low-profile-simple.dae" scale="1 1 1"/-->
      </geometry>
      <origin rpy="-1.5708 -1.5708 0" xyz="0 0 0"/>
      <material name="blue">
        <color rgba="0 0 .8 1"/>
      </material>
    </collision>
    <inertial>
      <mass value="0.001"/>
      <inertia ixx="0.001" ixy="0.0" ixz="0.0" iyy="0.001" iyz="0.0" izz="0.001"/>
    </inertial>
  </link>
  <link name="lpleft_servo_servo_body">
    <visual>
      <geometry>
        <box size=".040 .02 .0365"/>
      </geometry>
      <origin rpy="0 0 0" xyz="0 0 -0.00825"/>
      <material name="black">
        <color rgba=".1 .1 1 1"/>
      </material>
    </visual>
    <collision>
      <geometry>
        <box size=".040 .02 .0365"/>
      </geometry>
      <origin rpy="0 0 0" xyz="0 0 -0.00825"/>
    </collision>
    <inertial>
      <mass value="0.055"/>
      <inertia ixx="0.001" ixy="0.0" ixz="0.0" iyy="0.001" iyz="0.0" izz="0.001"/>
    </inertial>
  </link>
  <joint name="lpleft_lp_to_servo" type="fixed">
    <parent link="lpleft"/>
    <child link="lpleft_servo_servo_body"/>
    <origin rpy="0 1.5708 1.5708" xyz="-0.0397 0.0 0.0097"/>
  </joint>
  <joint name="LAnkleRotate" type="revolute">
    <axis xyz="0 -1 0"/>
    <limit effort="1000.0" lower="-1.5708" upper="1.5708" velocity="0.5"/>
    <parent link="lshin1"/>
    <child link="lpleft"/>
    <origin rpy="0 0 0" xyz="0.0078 -0.0281 -0.008"/>
  </joint>
  <link name="lshin2">
    <visual>
      <geometry>
        <mesh filename="package://george/meshes/cbracket-simple.dae" scale="1 1 1"/>
      </geometry>
      <origin rpy="-1.5708 0 0" xyz="0 0 0"/>
      <material name="blue">
        <color rgba="0 0 .8 1"/>
      </material>
    </visual>
    <collision>
      <geometry>
        <box size=".005 .005 .005"/>
        <!--  mesh filename="package://george/meshes/cbracket-simple.dae" scale="1 1 1"/-->
      </geometry>
      <origin rpy="-1.5708 0 0" xyz="0 0 0"/>
    </collision>
    <inertial>
      <mass value="0.001"/>
      <inertia ixx="0.001" ixy="0.0" ixz="0.0" iyy="0.001" iyz="0.0" izz="0.001"/>
    </inertial>
  </link>
  <joint name="lpleft_to_lshin2" type="fixed">
    <parent link="lpleft"/>
    <child link="lshin2"/>
    <origin rpy="-1.5708 0 0" xyz="0 0 0"/>
  </joint>
  <link name="LAnkleTilt_servo_body">
    <visual>
      <geometry>
        <box size=".040 .02 .0365"/>
      </geometry>
      <origin rpy="0 0 0" xyz="0.0161 0 -0.00825"/>
      <material name="black">
        <color rgba=".1 .1 1 1"/>
      </material>
    </visual>
    <collision>
      <geometry>
        <box size=".040 .02 .0365"/>
      </geometry>
      <origin rpy="0 0 0" xyz="0.0161 0 -0.00825"/>
    </collision>
    <inertial>
      <mass value="0.055"/>
      <inertia ixx="0.001" ixy="0.0" ixz="0.0" iyy="0.001" iyz="0.0" izz="0.001"/>
    </inertial>
  </link>
  <link name="LAnkleTilt_servo_lip">
    <visual>
      <geometry>
        <box size=".0528 .02 .002"/>
      </geometry>
      <origin rpy="0 0 0.001" xyz="0 0 0"/>
      <material name="black">
        <color rgba=".1 .1 1 1"/>
      </material>
    </visual>
    <collision>
      <geometry>
        <box size=".0528 .02 .002"/>
      </geometry>
      <origin rpy="0 0 0.001" xyz="0 0 0"/>
    </collision>
    <inertial>
      <mass value="0.001"/>
      <inertia ixx="0.001" ixy="0.0" ixz="0.0" iyy="0.001" iyz="0.0" izz="0.001"/>
    </inertial>
  </link>
  <link name="LAnkleTilt_servo_horn">
    <visual>
      <geometry>
        <cylinder length="0.001" radius="0.012"/>
      </geometry>
      <origin rpy="0 0 0" xyz="0 0 -.0005"/>
      <material name="white">
        <color rgba="1 1 1 1"/>
      </material>
    </visual>
    <collision>
      <geometry>
        <cylinder length="0.001" radius="0.012"/>
      </geometry>
      <origin rpy="0 0 0" xyz="0 0 -.0005"/>
    </collision>
    <inertial>
      <mass value="0.001"/>
      <inertia ixx="0.001" ixy="0.0" ixz="0.0" iyy="0.001" iyz="0.0" izz="0.001"/>
    </inertial>
  </link>
  <joint name="LAnkleTilt_servo_lip_to_body" type="fixed">
    <parent link="LAnkleTilt_servo_body"/>
    <child link="LAnkleTilt_servo_lip"/>
    <origin xyz="0.0161 0 0"/>
  </joint>
  <joint name="LAnkleTilt" type="revolute">
    <axis xyz="0 0 1"/>
    <limit effort="1000.0" lower="-1.5708" upper="1.5708" velocity="0.5"/>
    <parent link="LAnkleTilt_servo_horn"/>
    <child link="LAnkleTilt_servo_body"/>
    <origin rpy="0 0 -1.5708" xyz="0.0 0 -0.0161"/>
  </joint>
  <joint name="lshin2_to_lankletwist" type="fixed">
    <parent link="lshin2"/>
    <child link="LAnkleTilt_servo_horn"/>
    <origin rpy="0 -1.5708 0" xyz="-0.0246 0 -0.0286"/>
  </joint>
  <link name="lshin3">
    <visual>
      <geometry>
        <mesh filename="package://george/meshes/multi-purp-simple.dae" scale="1 1 1"/>
      </geometry>
      <origin rpy="0 3.1416 0" xyz="0.0161 -0.0142 -0.0144"/>
      <material name="blue">
        <color rgba="0 0 .8 1"/>
      </material>
    </visual>
    <collision>
      <geometry>
        <box size=".005 .005 .005"/>
        <!--  mesh filename="package://george/meshes/multi-purp-simple.dae" scale="1 1 1"/-->
      </geometry>
      <origin rpy="0 3.1416 0" xyz="0.0161 -0.0142 -0.0144"/>
    </collision>
    <inertial>
      <mass value="0.001"/>
      <inertia ixx="0.001" ixy="0.0" ixz="0.0" iyy="0.001" iyz="0.0" izz="0.001"/>
    </inertial>
  </link>
  <joint name="lankletwist_to_lshin3" type="fixed">
    <parent link="LAnkleTilt_servo_body"/>
    <child link="lshin3"/>
    <origin rpy="0 0 0" xyz="0 0 0"/>
  </joint>
  <link name="lfoot">
    <visual>
      <geometry>
        <mesh filename="package://george/meshes/foot.dae"/>
      </geometry>
      <origin rpy="0 0 0" xyz="0 0 0"/>
      <material name="blue">
        <color rgba="0 0 .8 1"/>
      </material>
    </visual>
    <collision>
      <geometry>
        <box size="0.065 0.002 0.15"/>
      </geometry>
      <origin rpy="0 0 0" xyz="0 0 0"/>
    </collision>
    <inertial>
      <mass value="0.001"/>
      <inertia ixx="0.001" ixy="0.0" ixz="0.0" iyy="0.001" iyz="0.0" izz="0.001"/>
    </inertial>
  </link>
  <joint name="lshin3_to_lfoot" type="fixed">
    <parent link="lshin3"/>
    <child link="lfoot"/>
    <origin rpy="0 3.1416 0" xyz="0.0161 -0.0156 -0.0"/>
  </joint>
  <!-- *********************************************************** -->
  <!-- ***** Right Leg ******************************************* -->
  <!-- *********************************************************** -->
  <link name="RWaist_servo_body">
    <visual>
      <geometry>
        <box size=".040 .02 .0365"/>
      </geometry>
      <origin rpy="0 0 0" xyz="0 0 -0.00825"/>
      <material name="black">
        <color rgba=".1 .1 1 1"/>
      </material>
    </visual>
    <collision>
      <geometry>
        <box size=".040 .02 .0365"/>
      </geometry>
      <origin rpy="0 0 0" xyz="0 0 -0.00825"/>
    </collision>
    <inertial>
      <mass value="0.055"/>
      <inertia ixx="0.001" ixy="0.0" ixz="0.0" iyy="0.001" iyz="0.0" izz="0.001"/>
    </inertial>
  </link>
  <link name="RWaist_servo_lip">
    <visual>
      <geometry>
        <box size=".0528 .02 .002"/>
      </geometry>
      <origin rpy="0 0 0.001" xyz="0 0 0"/>
      <material name="black">
        <color rgba=".1 .1 1 1"/>
      </material>
    </visual>
    <collision>
      <geometry>
        <box size=".0528 .02 .002"/>
      </geometry>
      <origin rpy="0 0 0.001" xyz="0 0 0"/>
    </collision>
    <inertial>
      <mass value="0.001"/>
      <inertia ixx="0.001" ixy="0.0" ixz="0.0" iyy="0.001" iyz="0.0" izz="0.001"/>
    </inertial>
  </link>
  <link name="RWaist_servo_horn">
    <visual>
      <geometry>
        <cylinder length="0.001" radius="0.012"/>
      </geometry>
      <origin rpy="0 0 0" xyz="0 0 -.0005"/>
      <material name="white">
        <color rgba="1 1 1 1"/>
      </material>
    </visual>
    <collision>
      <geometry>
        <cylinder length="0.001" radius="0.012"/>
      </geometry>
      <origin rpy="0 0 0" xyz="0 0 -.0005"/>
    </collision>
    <inertial>
      <mass value="0.001"/>
      <inertia ixx="0.001" ixy="0.0" ixz="0.0" iyy="0.001" iyz="0.0" izz="0.001"/>
    </inertial>
  </link>
  <joint name="RWaist_servo_lip_to_body" type="fixed">
    <parent link="RWaist_servo_body"/>
    <child link="RWaist_servo_lip"/>
    <origin xyz="0 0 0"/>
  </joint>
  <joint name="RWaist" type="revolute">
    <axis xyz="0 0 -1"/>
    <limit effort="1000.0" lower="-1.5708" upper="1.5708" velocity="0.5"/>
    <parent link="RWaist_servo_body"/>
    <child link="RWaist_servo_horn"/>
    <origin rpy="0 0 1.5708" xyz=".01 0 0.0161"/>
  </joint>
  <joint name="torso_to_rwaist" type="fixed">
    <parent link="base_link"/>
    <child link="RWaist_servo_body"/>
    <origin rpy="1.5708 1.5708 0" xyz="-0.032 0.005 0.03"/>
  </joint>
  <link name="rthigh1">
    <visual>
      <geometry>
        <mesh filename="package://george/meshes/cbracket-simple.dae" scale="1 1 1"/>
      </geometry>
      <origin rpy="0 1.5708 0" xyz="0 -0.0286 -0.0246"/>
      <material name="blue">
        <color rgba="0 0 .8 1"/>
      </material>
    </visual>
    <collision>
      <geometry>
        <box size=".005 .005 .005"/>
        <!--  mesh filename="package://george/meshes/cbracket-simple.dae" scale="1 1 1"/-->
      </geometry>
      <origin rpy="0 1.5708 0" xyz="0 -0.0286 -0.0246"/>
    </collision>
    <inertial>
      <mass value="0.001"/>
      <inertia ixx="0.001" ixy="0.0" ixz="0.0" iyy="0.001" iyz="0.0" izz="0.001"/>
    </inertial>
  </link>
  <joint name="rthigh1_to_rwaist" type="fixed">
    <parent link="RWaist_servo_horn"/>
    <child link="rthigh1"/>
    <origin rpy="0 0 0" xyz="0 0 0"/>
  </joint>
  <link name="rthigh2">
    <visual>
      <geometry>
        <mesh filename="package://george/meshes/multi-purp-simple.dae" scale="1 1 1"/>
      </geometry>
      <origin rpy="-1.5708 0 1.5708" xyz="0 0 0"/>
      <material name="blue">
        <color rgba="0 0 .8 1"/>
      </material>
    </visual>
    <collision>
      <geometry>
        <box size=".005 .005 .005"/>
        <!--  mesh filename="package://george/meshes/multi-purp-simple.dae" scale="1 1 1"/-->
      </geometry>
      <origin rpy="-1.5708 0 1.5708" xyz="0 0 0"/>
    </collision>
    <inertial>
      <mass value="0.001"/>
      <inertia ixx="0.001" ixy="0.0" ixz="0.0" iyy="0.001" iyz="0.0" izz="0.001"/>
    </inertial>
  </link>
  <joint name="rthigh1_to_rthigh2" type="fixed">
    <parent link="rthigh1"/>
    <child link="rthigh2"/>
    <origin rpy="-1.5708 3.1416 0" xyz="+0.0054 -0.0286 -0.0329"/>
  </joint>
  <link name="RHip_servo_body">
    <visual>
      <geometry>
        <box size=".040 .02 .0365"/>
      </geometry>
      <origin rpy="0 0 0" xyz="0 0 -0.00825"/>
      <material name="black">
        <color rgba=".1 .1 1 1"/>
      </material>
    </visual>
    <collision>
      <geometry>
        <box size=".040 .02 .0365"/>
      </geometry>
      <origin rpy="0 0 0" xyz="0 0 -0.00825"/>
    </collision>
    <inertial>
      <mass value="0.055"/>
      <inertia ixx="0.001" ixy="0.0" ixz="0.0" iyy="0.001" iyz="0.0" izz="0.001"/>
    </inertial>
  </link>
  <link name="RHip_servo_lip">
    <visual>
      <geometry>
        <box size=".0528 .02 .002"/>
      </geometry>
      <origin rpy="0 0 0.001" xyz="0 0 0"/>
      <material name="black">
        <color rgba=".1 .1 1 1"/>
      </material>
    </visual>
    <collision>
      <geometry>
        <box size=".0528 .02 .002"/>
      </geometry>
      <origin rpy="0 0 0.001" xyz="0 0 0"/>
    </collision>
    <inertial>
      <mass value="0.001"/>
      <inertia ixx="0.001" ixy="0.0" ixz="0.0" iyy="0.001" iyz="0.0" izz="0.001"/>
    </inertial>
  </link>
  <link name="RHip_servo_horn">
    <visual>
      <geometry>
        <cylinder length="0.001" radius="0.012"/>
      </geometry>
      <origin rpy="0 0 0" xyz="0 0 -.0005"/>
      <material name="white">
        <color rgba="1 1 1 1"/>
      </material>
    </visual>
    <collision>
      <geometry>
        <cylinder length="0.001" radius="0.012"/>
      </geometry>
      <origin rpy="0 0 0" xyz="0 0 -.0005"/>
    </collision>
    <inertial>
      <mass value="0.001"/>
      <inertia ixx="0.001" ixy="0.0" ixz="0.0" iyy="0.001" iyz="0.0" izz="0.001"/>
    </inertial>
  </link>
  <joint name="RHip_servo_lip_to_body" type="fixed">
    <parent link="RHip_servo_body"/>
    <child link="RHip_servo_lip"/>
    <origin xyz="0 0 0"/>
  </joint>
  <joint name="RHip" type="revolute">
    <axis xyz="0 0 -1"/>
    <limit effort="1000.0" lower="-1.5708" upper="1.5708" velocity="0.5"/>
    <parent link="RHip_servo_body"/>
    <child link="RHip_servo_horn"/>
    <origin rpy="0 0 0" xyz=".01 0 0.0161"/>
  </joint>
  <joint name="rthigh2_to_rhip" type="fixed">
    <parent link="rthigh2"/>
    <child link="RHip_servo_body"/>
    <origin rpy="-1.5708 3.1416 -1.5708" xyz="0.0144 0 -0.0142"/>
  </joint>
  <link name="rthigh3">
    <visual>
      <geometry>
        <mesh filename="package://george/meshes/cbracket-simple.dae" scale="1 1 1"/>
      </geometry>
      <origin rpy="0 1.5708 0" xyz="0 -0.0286 -0.0246"/>
      <material name="blue">
        <color rgba="0 0 .8 1"/>
      </material>
    </visual>
    <collision>
      <geometry>
        <box size=".005 .005 .005"/>
        <!--  mesh filename="package://george/meshes/cbracket-simple.dae" scale="1 1 1"/-->
      </geometry>
      <origin rpy="0 1.5708 0" xyz="0 -0.0286 -0.0246"/>
    </collision>
    <inertial>
      <mass value="0.001"/>
      <inertia ixx="0.001" ixy="0.0" ixz="0.0" iyy="0.001" iyz="0.0" izz="0.001"/>
    </inertial>
  </link>
  <joint name="rthigh3_to_rhip" type="fixed">
    <parent link="RHip_servo_horn"/>
    <child link="rthigh3"/>
    <origin rpy="0 0 0" xyz="0 0 0"/>
  </joint>
  <link name="rthigh4">
    <visual>
      <geometry>
        <mesh filename="package://george/meshes/cbracket-simple.dae" scale="1 1 1"/>
      </geometry>
      <origin rpy="-1.5708 0 0" xyz="0 0 0"/>
      <material name="blue">
        <color rgba="0 0 .8 1"/>
      </material>
    </visual>
    <collision>
      <geometry>
        <box size=".005 .005 .005"/>
        <!--  mesh filename="package://george/meshes/cbracket-simple.dae" scale="1 1 1"/-->
      </geometry>
      <origin rpy="-1.5708 0 0" xyz="0 0 0"/>
    </collision>
    <inertial>
      <mass value="0.001"/>
      <inertia ixx="0.001" ixy="0.0" ixz="0.0" iyy="0.001" iyz="0.0" izz="0.001"/>
    </inertial>
  </link>
  <joint name="rthigh3_to_rthigh4" type="fixed">
    <parent link="rthigh3"/>
    <child link="rthigh4"/>
    <origin rpy="-1.5708 1.5708 0" xyz="0 -0.0286 -0.0246"/>
  </joint>
  <link name="RKnee_servo_body">
    <visual>
      <geometry>
        <box size=".040 .02 .0365"/>
      </geometry>
      <origin rpy="0 0 0" xyz="0.0161 0 -0.00825"/>
      <material name="black">
        <color rgba=".1 .1 1 1"/>
      </material>
    </visual>
    <collision>
      <geometry>
        <box size=".040 .02 .0365"/>
      </geometry>
      <origin rpy="0 0 0" xyz="0.0161 0 -0.00825"/>
    </collision>
    <inertial>
      <mass value="0.055"/>
      <inertia ixx="0.001" ixy="0.0" ixz="0.0" iyy="0.001" iyz="0.0" izz="0.001"/>
    </inertial>
  </link>
  <link name="RKnee_servo_lip">
    <visual>
      <geometry>
        <box size=".0528 .02 .002"/>
      </geometry>
      <origin rpy="0 0 0.001" xyz="0 0 0"/>
      <material name="black">
        <color rgba=".1 .1 1 1"/>
      </material>
    </visual>
    <collision>
      <geometry>
        <box size=".0528 .02 .002"/>
      </geometry>
      <origin rpy="0 0 0.001" xyz="0 0 0"/>
    </collision>
    <inertial>
      <mass value="0.001"/>
      <inertia ixx="0.001" ixy="0.0" ixz="0.0" iyy="0.001" iyz="0.0" izz="0.001"/>
    </inertial>
  </link>
  <link name="RKnee_servo_horn">
    <visual>
      <geometry>
        <cylinder length="0.001" radius="0.012"/>
      </geometry>
      <origin rpy="0 0 0" xyz="0 0 -.0005"/>
      <material name="white">
        <color rgba="1 1 1 1"/>
      </material>
    </visual>
    <collision>
      <geometry>
        <cylinder length="0.001" radius="0.012"/>
      </geometry>
      <origin rpy="0 0 0" xyz="0 0 -.0005"/>
    </collision>
    <inertial>
      <mass value="0.001"/>
      <inertia ixx="0.001" ixy="0.0" ixz="0.0" iyy="0.001" iyz="0.0" izz="0.001"/>
    </inertial>
  </link>
  <joint name="RKnee_servo_lip_to_body" type="fixed">
    <parent link="RKnee_servo_body"/>
    <child link="RKnee_servo_lip"/>
    <origin xyz="0.0161 0 0"/>
  </joint>
  <joint name="RKnee" type="revolute">
    <axis xyz="0 0 1"/>
    <limit effort="1000.0" lower="-1.5708" upper="1.5708" velocity="0.5"/>
    <parent link="RKnee_servo_horn"/>
    <child link="RKnee_servo_body"/>
    <origin rpy="0 0 -1.5708" xyz="0.0 0 -0.0161"/>
  </joint>
  <joint name="rthigh4_to_knee" type="fixed">
    <parent link="rthigh4"/>
    <child link="RKnee_servo_horn"/>
    <origin rpy="0 -1.5708 0" xyz="-0.0246 0 -0.0286"/>
  </joint>
  <link name="rknee1">
    <visual>
      <geometry>
        <mesh filename="package://george/meshes/multi-purp-simple.dae" scale="1 1 1"/>
      </geometry>
      <origin rpy="0 3.1416 0" xyz="0.0161 -0.0142 -0.0144"/>
      <material name="blue">
        <color rgba="0 0 .8 1"/>
      </material>
    </visual>
    <collision>
      <geometry>
        <box size=".005 .005 .005"/>
        <!--  mesh filename="package://george/meshes/multi-purp-simple.dae" scale="1 1 1"/-->
      </geometry>
      <origin rpy="0 3.1416 0" xyz="0.0161 -0.0142 -0.0144"/>
    </collision>
    <inertial>
      <mass value="0.001"/>
      <inertia ixx="0.001" ixy="0.0" ixz="0.0" iyy="0.001" iyz="0.0" izz="0.001"/>
    </inertial>
  </link>
  <joint name="rknee_to_rknee1" type="fixed">
    <parent link="RKnee_servo_body"/>
    <child link="rknee1"/>
    <origin rpy="0 0 0" xyz="0 0 0"/>
  </joint>
  <link name="rknee2">
    <visual>
      <geometry>
        <mesh filename="package://george/meshes/cbracket-simple.dae" scale="1 1 1"/>
      </geometry>
      <origin rpy="-1.5708 0 0" xyz="0 0 0"/>
      <material name="blue">
        <color rgba="0 0 .8 1"/>
      </material>
    </visual>
    <collision>
      <geometry>
        <box size=".005 .005 .005"/>
        <!--  mesh filename="package://george/meshes/cbracket-simple.dae" scale="1 1 1"/-->
      </geometry>
      <origin rpy="-1.5708 0 0" xyz="0 0 0"/>
    </collision>
    <inertial>
      <mass value="0.001"/>
      <inertia ixx="0.001" ixy="0.0" ixz="0.0" iyy="0.001" iyz="0.0" izz="0.001"/>
    </inertial>
  </link>
  <joint name="rknee1_to_rknee2" type="fixed">
    <parent link="rknee1"/>
    <child link="rknee2"/>
    <origin rpy="-1.5708 1.5708 0" xyz="0.0078 -0.0141 -0.008"/>
  </joint>
  <link name="RAnkleBend_servo_body">
    <visual>
      <geometry>
        <box size=".040 .02 .0365"/>
      </geometry>
      <origin rpy="0 0 0" xyz="0.0161 0 -0.00825"/>
      <material name="black">
        <color rgba=".1 .1 1 1"/>
      </material>
    </visual>
    <collision>
      <geometry>
        <box size=".040 .02 .0365"/>
      </geometry>
      <origin rpy="0 0 0" xyz="0.0161 0 -0.00825"/>
    </collision>
    <inertial>
      <mass value="0.055"/>
      <inertia ixx="0.001" ixy="0.0" ixz="0.0" iyy="0.001" iyz="0.0" izz="0.001"/>
    </inertial>
  </link>
  <link name="RAnkleBend_servo_lip">
    <visual>
      <geometry>
        <box size=".0528 .02 .002"/>
      </geometry>
      <origin rpy="0 0 0.001" xyz="0 0 0"/>
      <material name="black">
        <color rgba=".1 .1 1 1"/>
      </material>
    </visual>
    <collision>
      <geometry>
        <box size=".0528 .02 .002"/>
      </geometry>
      <origin rpy="0 0 0.001" xyz="0 0 0"/>
    </collision>
    <inertial>
      <mass value="0.001"/>
      <inertia ixx="0.001" ixy="0.0" ixz="0.0" iyy="0.001" iyz="0.0" izz="0.001"/>
    </inertial>
  </link>
  <link name="RAnkleBend_servo_horn">
    <visual>
      <geometry>
        <cylinder length="0.001" radius="0.012"/>
      </geometry>
      <origin rpy="0 0 0" xyz="0 0 -.0005"/>
      <material name="white">
        <color rgba="1 1 1 1"/>
      </material>
    </visual>
    <collision>
      <geometry>
        <cylinder length="0.001" radius="0.012"/>
      </geometry>
      <origin rpy="0 0 0" xyz="0 0 -.0005"/>
    </collision>
    <inertial>
      <mass value="0.001"/>
      <inertia ixx="0.001" ixy="0.0" ixz="0.0" iyy="0.001" iyz="0.0" izz="0.001"/>
    </inertial>
  </link>
  <joint name="RAnkleBend_servo_lip_to_body" type="fixed">
    <parent link="RAnkleBend_servo_body"/>
    <child link="RAnkleBend_servo_lip"/>
    <origin xyz="0.0161 0 0"/>
  </joint>
  <joint name="RAnkleBend" type="revolute">
    <axis xyz="0 0 1"/>
    <limit effort="1000.0" lower="-1.5708" upper="1.5708" velocity="0.5"/>
    <parent link="RAnkleBend_servo_horn"/>
    <child link="RAnkleBend_servo_body"/>
    <origin rpy="0 0 1.5708" xyz="0.0 0 -0.0161"/>
  </joint>
  <joint name="rknee2_to_ranklebend" type="fixed">
    <parent link="rknee2"/>
    <child link="RAnkleBend_servo_horn"/>
    <origin rpy="0 -1.5708 0" xyz="-0.0246 0 -0.0286"/>
  </joint>
  <link name="rshin1">
    <visual>
      <geometry>
        <mesh filename="package://george/meshes/multi-purp-simple.dae" scale="1 1 1"/>
      </geometry>
      <origin rpy="0 3.1416 3.1416" xyz="0.0161 0.0142 -0.0144"/>
      <material name="blue">
        <color rgba="0 0 .8 1"/>
      </material>
    </visual>
    <collision>
      <geometry>
        <box size=".005 .005 .005"/>
        <!--  mesh filename="package://george/meshes/multi-purp-simple.dae" scale="1 1 1"/-->
      </geometry>
      <origin rpy="0 3.1416 3.1416" xyz="0.0161 0.0142 -0.0144"/>
    </collision>
    <inertial>
      <mass value="0.001"/>
      <inertia ixx="0.001" ixy="0.0" ixz="0.0" iyy="0.001" iyz="0.0" izz="0.001"/>
    </inertial>
  </link>
  <joint name="ranklebend_to_rshin1" type="fixed">
    <parent link="RAnkleBend_servo_body"/>
    <child link="rshin1"/>
    <origin rpy="0 0 0" xyz="0 0 0"/>
  </joint>
  <link name="lpright">
    <visual>
      <geometry>
        <mesh filename="package://george/meshes/low-profile-simple.dae" scale="1 1 1"/>
      </geometry>
      <origin rpy="-1.5708 -1.5708 0" xyz="0 0 0"/>
      <material name="blue">
        <color rgba="0 0 .8 1"/>
      </material>
    </visual>
    <collision>
      <geometry>
        <box size=".005 .005 .005"/>
        <!--  mesh filename="package://george/meshes/low-profile-simple.dae" scale="1 1 1"/-->
      </geometry>
      <origin rpy="-1.5708 -1.5708 0" xyz="0 0 0"/>
      <material name="blue">
        <color rgba="0 0 .8 1"/>
      </material>
    </collision>
    <inertial>
      <mass value="0.001"/>
      <inertia ixx="0.001" ixy="0.0" ixz="0.0" iyy="0.001" iyz="0.0" izz="0.001"/>
    </inertial>
  </link>
  <link name="lpright_servo_servo_body">
    <visual>
      <geometry>
        <box size=".040 .02 .0365"/>
      </geometry>
      <origin rpy="0 0 0" xyz="0 0 -0.00825"/>
      <material name="black">
        <color rgba=".1 .1 1 1"/>
      </material>
    </visual>
    <collision>
      <geometry>
        <box size=".040 .02 .0365"/>
      </geometry>
      <origin rpy="0 0 0" xyz="0 0 -0.00825"/>
    </collision>
    <inertial>
      <mass value="0.055"/>
      <inertia ixx="0.001" ixy="0.0" ixz="0.0" iyy="0.001" iyz="0.0" izz="0.001"/>
    </inertial>
  </link>
  <joint name="lpright_lp_to_servo" type="fixed">
    <parent link="lpright"/>
    <child link="lpright_servo_servo_body"/>
    <origin rpy="0 1.5708 1.5708" xyz="-0.0397 0.0165 0.0097"/>
  </joint>
  <joint name="RAnkleRotate" type="revolute">
    <axis xyz="0 1 0"/>
    <limit effort="1000.0" lower="-1.5708" upper="1.5708" velocity="0.5"/>
    <parent link="rshin1"/>
    <child link="lpright"/>
    <origin rpy="0 0 0" xyz="0.0078 0.0281 -0.008"/>
  </joint>
  <link name="rshin2">
    <visual>
      <geometry>
        <mesh filename="package://george/meshes/cbracket-simple.dae" scale="1 1 1"/>
      </geometry>
      <origin rpy="-1.5708 0 0" xyz="0 0 0"/>
      <material name="blue">
        <color rgba="0 0 .8 1"/>
      </material>
    </visual>
    <collision>
      <geometry>
        <box size=".005 .005 .005"/>
        <!--  mesh filename="package://george/meshes/cbracket-simple.dae" scale="1 1 1"/-->
      </geometry>
      <origin rpy="-1.5708 0 0" xyz="0 0 0"/>
    </collision>
    <inertial>
      <mass value="0.001"/>
      <inertia ixx="0.001" ixy="0.0" ixz="0.0" iyy="0.001" iyz="0.0" izz="0.001"/>
    </inertial>
  </link>
  <joint name="rshin1_to_rshin2" type="fixed">
    <parent link="lpright"/>
    <child link="rshin2"/>
    <origin rpy="1.5708 0 0" xyz="0 0.002 0"/>
  </joint>
  <link name="RAnkleTilt_servo_body">
    <visual>
      <geometry>
        <box size=".040 .02 .0365"/>
      </geometry>
      <origin rpy="0 0 0" xyz="0.0161 0 -0.00825"/>
      <material name="black">
        <color rgba=".1 .1 1 1"/>
      </material>
    </visual>
    <collision>
      <geometry>
        <box size=".040 .02 .0365"/>
      </geometry>
      <origin rpy="0 0 0" xyz="0.0161 0 -0.00825"/>
    </collision>
    <inertial>
      <mass value="0.055"/>
      <inertia ixx="0.001" ixy="0.0" ixz="0.0" iyy="0.001" iyz="0.0" izz="0.001"/>
    </inertial>
  </link>
  <link name="RAnkleTilt_servo_lip">
    <visual>
      <geometry>
        <box size=".0528 .02 .002"/>
      </geometry>
      <origin rpy="0 0 0.001" xyz="0 0 0"/>
      <material name="black">
        <color rgba=".1 .1 1 1"/>
      </material>
    </visual>
    <collision>
      <geometry>
        <box size=".0528 .02 .002"/>
      </geometry>
      <origin rpy="0 0 0.001" xyz="0 0 0"/>
    </collision>
    <inertial>
      <mass value="0.001"/>
      <inertia ixx="0.001" ixy="0.0" ixz="0.0" iyy="0.001" iyz="0.0" izz="0.001"/>
    </inertial>
  </link>
  <link name="RAnkleTilt_servo_horn">
    <visual>
      <geometry>
        <cylinder length="0.001" radius="0.012"/>
      </geometry>
      <origin rpy="0 0 0" xyz="0 0 -.0005"/>
      <material name="white">
        <color rgba="1 1 1 1"/>
      </material>
    </visual>
    <collision>
      <geometry>
        <cylinder length="0.001" radius="0.012"/>
      </geometry>
      <origin rpy="0 0 0" xyz="0 0 -.0005"/>
    </collision>
    <inertial>
      <mass value="0.001"/>
      <inertia ixx="0.001" ixy="0.0" ixz="0.0" iyy="0.001" iyz="0.0" izz="0.001"/>
    </inertial>
  </link>
  <joint name="RAnkleTilt_servo_lip_to_body" type="fixed">
    <parent link="RAnkleTilt_servo_body"/>
    <child link="RAnkleTilt_servo_lip"/>
    <origin xyz="0.0161 0 0"/>
  </joint>
  <joint name="RAnkleTilt" type="revolute">
    <axis xyz="0 0 1"/>
    <limit effort="1000.0" lower="-1.5708" upper="1.5708" velocity="0.5"/>
    <parent link="RAnkleTilt_servo_horn"/>
    <child link="RAnkleTilt_servo_body"/>
    <origin rpy="0 0 1.5708" xyz="0.0 0 -0.0161"/>
  </joint>
  <joint name="rshin2_to_RAnkleTilt" type="fixed">
    <parent link="rshin2"/>
    <child link="RAnkleTilt_servo_horn"/>
    <origin rpy="0 -1.5708 0" xyz="-0.0246 0 -0.0286"/>
  </joint>
  <link name="rshin3">
    <visual>
      <geometry>
        <mesh filename="package://george/meshes/multi-purp-simple.dae" scale="1 1 1"/>
      </geometry>
      <origin rpy="0 3.1416 3.1416" xyz="0.0161 0.0142 -0.0144"/>
      <material name="blue">
        <color rgba="0 0 .8 1"/>
      </material>
    </visual>
    <collision>
      <geometry>
        <box size=".005 .005 .005"/>
        <!--  mesh filename="package://george/meshes/multi-purp-simple.dae" scale="1 1 1"/-->
      </geometry>
      <origin rpy="0 3.1416 3.1416" xyz="0.0161 0.0142 -0.0144"/>
    </collision>
    <inertial>
      <mass value="0.001"/>
      <inertia ixx="0.001" ixy="0.0" ixz="0.0" iyy="0.001" iyz="0.0" izz="0.001"/>
    </inertial>
  </link>
  <joint name="rankletwist_to_rshin3" type="fixed">
    <parent link="RAnkleTilt_servo_body"/>
    <child link="rshin3"/>
    <origin rpy="0 0 0" xyz="0 0 0"/>
  </joint>
  <link name="rfoot">
    <visual>
      <geometry>
        <mesh filename="package://george/meshes/foot.dae"/>
      </geometry>
      <origin rpy="0 0 0" xyz="0 0 0"/>
      <material name="blue">
        <color rgba="0 0 .8 1"/>
      </material>
    </visual>
    <collision>
      <geometry>
        <box size="0.065 0.002 0.15"/>
      </geometry>
      <origin rpy="0 0 0" xyz="0 0 0"/>
    </collision>
    <inertial>
      <mass value="0.001"/>
      <inertia ixx="0.001" ixy="0.0" ixz="0.0" iyy="0.001" iyz="0.0" izz="0.001"/>
    </inertial>
  </link>
  <joint name="rshin3_to_rfoot" type="fixed">
    <parent link="rshin3"/>
    <child link="rfoot"/>
    <origin rpy="3.1416 0 0" xyz="0.0161 0.0156 -0.0"/>
  </joint>
  <!-- *********************************************************** -->
  <!-- ***** Left Arm  ******************************************* -->
  <!-- *********************************************************** -->
  <link name="LShoulder_servo_body">
    <visual>
      <geometry>
        <box size=".040 .02 .0365"/>
      </geometry>
      <origin rpy="0 0 0" xyz="0 0 -0.00825"/>
      <material name="black">
        <color rgba=".1 .1 1 1"/>
      </material>
    </visual>
    <collision>
      <geometry>
        <box size=".040 .02 .0365"/>
      </geometry>
      <origin rpy="0 0 0" xyz="0 0 -0.00825"/>
    </collision>
    <inertial>
      <mass value="0.055"/>
      <inertia ixx="0.001" ixy="0.0" ixz="0.0" iyy="0.001" iyz="0.0" izz="0.001"/>
    </inertial>
  </link>
  <link name="LShoulder_servo_lip">
    <visual>
      <geometry>
        <box size=".0528 .02 .002"/>
      </geometry>
      <origin rpy="0 0 0.001" xyz="0 0 0"/>
      <material name="black">
        <color rgba=".1 .1 1 1"/>
      </material>
    </visual>
    <collision>
      <geometry>
        <box size=".0528 .02 .002"/>
      </geometry>
      <origin rpy="0 0 0.001" xyz="0 0 0"/>
    </collision>
    <inertial>
      <mass value="0.001"/>
      <inertia ixx="0.001" ixy="0.0" ixz="0.0" iyy="0.001" iyz="0.0" izz="0.001"/>
    </inertial>
  </link>
  <link name="LShoulder_servo_horn">
    <visual>
      <geometry>
        <cylinder length="0.001" radius="0.012"/>
      </geometry>
      <origin rpy="0 0 0" xyz="0 0 -.0005"/>
      <material name="white">
        <color rgba="1 1 1 1"/>
      </material>
    </visual>
    <collision>
      <geometry>
        <cylinder length="0.001" radius="0.012"/>
      </geometry>
      <origin rpy="0 0 0" xyz="0 0 -.0005"/>
    </collision>
    <inertial>
      <mass value="0.001"/>
      <inertia ixx="0.001" ixy="0.0" ixz="0.0" iyy="0.001" iyz="0.0" izz="0.001"/>
    </inertial>
  </link>
  <joint name="LShoulder_servo_lip_to_body" type="fixed">
    <parent link="LShoulder_servo_body"/>
    <child link="LShoulder_servo_lip"/>
    <origin xyz="0 0 0"/>
  </joint>
  <joint name="LShoulder" type="revolute">
    <axis xyz="0 0 -1"/>
    <limit effort="1000.0" lower="-1.5708" upper="1.5708" velocity="0.5"/>
    <parent link="LShoulder_servo_body"/>
    <child link="LShoulder_servo_horn"/>
    <origin rpy="0 0 0" xyz=".01 0 0.0161"/>
  </joint>
  <joint name="torso_to_lshoulder" type="fixed">
    <parent link="base_link"/>
    <child link="LShoulder_servo_body"/>
    <origin rpy="-1.5708 0 -1.5708" xyz="0.0380 0.023175 0.071438"/>
  </joint>
  <link name="lshoulder1">
    <visual>
      <geometry>
        <mesh filename="package://george/meshes/offset-c-simple.dae" scale="1 1 1"/>
      </geometry>
      <origin rpy="1.5708 0 3.1416" xyz="0 0 0"/>
      <material name="blue">
        <color rgba="0 0 .8 1"/>
      </material>
    </visual>
    <collision>
      <geometry>
        <box size=".005 .005 .005"/>
        <!-- mesh filename="package://george/meshes/offset-c-simple.dae" scale="1 1 1"/-->
      </geometry>
      <origin rpy="1.5708 0 3.1416" xyz="0 0 0"/>
    </collision>
    <inertial>
      <mass value="0.001"/>
      <inertia ixx="0.001" ixy="0.0" ixz="0.0" iyy="0.001" iyz="0.0" izz="0.001"/>
    </inertial>
  </link>
  <joint name="lshoulder1_to_lshoulder" type="fixed">
    <parent link="LShoulder_servo_horn"/>
    <child link="lshoulder1"/>
    <origin rpy="0 0 -1.5708" xyz="0 0 0"/>
  </joint>
  <link name="LElbow_servo_body">
    <visual>
      <geometry>
        <box size=".040 .02 .0365"/>
      </geometry>
      <origin rpy="0 0 0" xyz="0.0161 0 -0.00825"/>
      <material name="black">
        <color rgba=".1 .1 1 1"/>
      </material>
    </visual>
    <collision>
      <geometry>
        <box size=".040 .02 .0365"/>
      </geometry>
      <origin rpy="0 0 0" xyz="0.0161 0 -0.00825"/>
    </collision>
    <inertial>
      <mass value="0.055"/>
      <inertia ixx="0.001" ixy="0.0" ixz="0.0" iyy="0.001" iyz="0.0" izz="0.001"/>
    </inertial>
  </link>
  <link name="LElbow_servo_lip">
    <visual>
      <geometry>
        <box size=".0528 .02 .002"/>
      </geometry>
      <origin rpy="0 0 0.001" xyz="0 0 0"/>
      <material name="black">
        <color rgba=".1 .1 1 1"/>
      </material>
    </visual>
    <collision>
      <geometry>
        <box size=".0528 .02 .002"/>
      </geometry>
      <origin rpy="0 0 0.001" xyz="0 0 0"/>
    </collision>
    <inertial>
      <mass value="0.001"/>
      <inertia ixx="0.001" ixy="0.0" ixz="0.0" iyy="0.001" iyz="0.0" izz="0.001"/>
    </inertial>
  </link>
  <link name="LElbow_servo_horn">
    <visual>
      <geometry>
        <cylinder length="0.001" radius="0.012"/>
      </geometry>
      <origin rpy="0 0 0" xyz="0 0 -.0005"/>
      <material name="white">
        <color rgba="1 1 1 1"/>
      </material>
    </visual>
    <collision>
      <geometry>
        <cylinder length="0.001" radius="0.012"/>
      </geometry>
      <origin rpy="0 0 0" xyz="0 0 -.0005"/>
    </collision>
    <inertial>
      <mass value="0.001"/>
      <inertia ixx="0.001" ixy="0.0" ixz="0.0" iyy="0.001" iyz="0.0" izz="0.001"/>
    </inertial>
  </link>
  <joint name="LElbow_servo_lip_to_body" type="fixed">
    <parent link="LElbow_servo_body"/>
    <child link="LElbow_servo_lip"/>
    <origin xyz="0.0161 0 0"/>
  </joint>
  <joint name="LElbow" type="revolute">
    <axis xyz="0 0 1"/>
    <limit effort="1000.0" lower="-1.5708" upper="1.5708" velocity="0.5"/>
    <parent link="LElbow_servo_horn"/>
    <child link="LElbow_servo_body"/>
    <origin rpy="0 0 0" xyz="0.0 0 -0.0161"/>
  </joint>
  <joint name="lelbow_to_shoulder1" type="fixed">
    <parent link="lshoulder1"/>
    <child link="LElbow_servo_horn"/>
    <origin rpy="0 -1.5708 0" xyz="-0.0246 -0.0187 0.027"/>
  </joint>
  <link name="lforearm1">
    <visual>
      <geometry>
        <mesh filename="package://george/meshes/multi-purp-simple.dae" scale="1 1 1"/>
      </geometry>
      <origin rpy="0 3.1416 0" xyz="0.0161 -0.0142 -0.0144"/>
      <material name="blue">
        <color rgba="0 0 .8 1"/>
      </material>
    </visual>
    <collision>
      <geometry>
        <box size=".005 .005 .005"/>
        <!--  mesh filename="package://george/meshes/multi-purp-simple.dae" scale="1 1 1"/-->
      </geometry>
      <origin rpy="0 3.1416 0" xyz="0.0161 -0.0142 -0.0144"/>
    </collision>
    <inertial>
      <mass value="0.001"/>
      <inertia ixx="0.001" ixy="0.0" ixz="0.0" iyy="0.001" iyz="0.0" izz="0.001"/>
    </inertial>
  </link>
  <joint name="lforearm1_to_lelbow" type="fixed">
    <parent link="LElbow_servo_body"/>
    <child link="lforearm1"/>
    <origin rpy="0 0 0" xyz="0 0 0"/>
  </joint>
  <link name="lforearm2">
    <visual>
      <geometry>
        <mesh filename="package://george/meshes/multi-purp-simple.dae" scale="1 1 1"/>
      </geometry>
      <origin rpy="-1.5708 0 1.5708" xyz="0 0 0"/>
      <material name="blue">
        <color rgba="0 0 .8 1"/>
      </material>
    </visual>
    <collision>
      <geometry>
        <box size=".005 .005 .005"/>
        <!--  mesh filename="package://george/meshes/multi-purp-simple.dae" scale="1 1 1"/-->
      </geometry>
      <origin rpy="-1.5708 0 1.5708" xyz="0 0 0"/>
    </collision>
    <inertial>
      <mass value="0.001"/>
      <inertia ixx="0.001" ixy="0.0" ixz="0.0" iyy="0.001" iyz="0.0" izz="0.001"/>
    </inertial>
  </link>
  <joint name="lforearm2_to_lforearm1" type="fixed">
    <parent link="lforearm1"/>
    <child link="lforearm2"/>
    <origin rpy="-1.5708 0 0" xyz="0.019 -0.0142 -0.0163"/>
  </joint>
  <link name="LWristTwist_servo_body">
    <visual>
      <geometry>
        <box size=".040 .02 .0365"/>
      </geometry>
      <origin rpy="0 0 0" xyz="0 0 -0.00825"/>
      <material name="black">
        <color rgba=".1 .1 1 1"/>
      </material>
    </visual>
    <collision>
      <geometry>
        <box size=".040 .02 .0365"/>
      </geometry>
      <origin rpy="0 0 0" xyz="0 0 -0.00825"/>
    </collision>
    <inertial>
      <mass value="0.055"/>
      <inertia ixx="0.001" ixy="0.0" ixz="0.0" iyy="0.001" iyz="0.0" izz="0.001"/>
    </inertial>
  </link>
  <link name="LWristTwist_servo_lip">
    <visual>
      <geometry>
        <box size=".0528 .02 .002"/>
      </geometry>
      <origin rpy="0 0 0.001" xyz="0 0 0"/>
      <material name="black">
        <color rgba=".1 .1 1 1"/>
      </material>
    </visual>
    <collision>
      <geometry>
        <box size=".0528 .02 .002"/>
      </geometry>
      <origin rpy="0 0 0.001" xyz="0 0 0"/>
    </collision>
    <inertial>
      <mass value="0.001"/>
      <inertia ixx="0.001" ixy="0.0" ixz="0.0" iyy="0.001" iyz="0.0" izz="0.001"/>
    </inertial>
  </link>
  <link name="LWristTwist_servo_horn">
    <visual>
      <geometry>
        <cylinder length="0.001" radius="0.012"/>
      </geometry>
      <origin rpy="0 0 0" xyz="0 0 -.0005"/>
      <material name="white">
        <color rgba="1 1 1 1"/>
      </material>
    </visual>
    <collision>
      <geometry>
        <cylinder length="0.001" radius="0.012"/>
      </geometry>
      <origin rpy="0 0 0" xyz="0 0 -.0005"/>
    </collision>
    <inertial>
      <mass value="0.001"/>
      <inertia ixx="0.001" ixy="0.0" ixz="0.0" iyy="0.001" iyz="0.0" izz="0.001"/>
    </inertial>
  </link>
  <joint name="LWristTwist_servo_lip_to_body" type="fixed">
    <parent link="LWristTwist_servo_body"/>
    <child link="LWristTwist_servo_lip"/>
    <origin xyz="0 0 0"/>
  </joint>
  <joint name="LWristTwist" type="revolute">
    <axis xyz="0 0 -1"/>
    <limit effort="1000.0" lower="-1.5708" upper="1.5708" velocity="0.5"/>
    <parent link="LWristTwist_servo_body"/>
    <child link="LWristTwist_servo_horn"/>
    <origin rpy="0 0 3.1416" xyz=".01 0 0.0161"/>
  </joint>
  <joint name="lwristtwist_to_lforearm2" type="fixed">
    <parent link="lforearm2"/>
    <child link="LWristTwist_servo_body"/>
    <origin rpy="1.5708 0 1.5708" xyz="0.0144 0 -0.0142"/>
  </joint>
  <link name="lforearm3">
    <visual>
      <geometry>
        <mesh filename="package://george/meshes/cbracket-simple.dae" scale="1 1 1"/>
      </geometry>
      <origin rpy="-1.5708 0 0" xyz="0 0 0"/>
      <material name="blue">
        <color rgba="0 0 .8 1"/>
      </material>
    </visual>
    <collision>
      <geometry>
        <box size=".005 .005 .005"/>
        <!--  mesh filename="package://george/meshes/cbracket-simple.dae" scale="1 1 1"/-->
      </geometry>
      <origin rpy="-1.5708 0 0" xyz="0 0 0"/>
    </collision>
    <inertial>
      <mass value="0.001"/>
      <inertia ixx="0.001" ixy="0.0" ixz="0.0" iyy="0.001" iyz="0.0" izz="0.001"/>
    </inertial>
  </link>
  <joint name="lforearm3_to_lwristtwist" type="fixed">
    <parent link="LWristTwist_servo_horn"/>
    <child link="lforearm3"/>
    <origin rpy="3.1416 0 0" xyz="0 0 0"/>
  </joint>
  <link name="LWristFlex_servo_body">
    <visual>
      <geometry>
        <box size=".040 .02 .0365"/>
      </geometry>
      <origin rpy="0 0 0" xyz="0.0161 0 -0.00825"/>
      <material name="black">
        <color rgba=".1 .1 1 1"/>
      </material>
    </visual>
    <collision>
      <geometry>
        <box size=".040 .02 .0365"/>
      </geometry>
      <origin rpy="0 0 0" xyz="0.0161 0 -0.00825"/>
    </collision>
    <inertial>
      <mass value="0.055"/>
      <inertia ixx="0.001" ixy="0.0" ixz="0.0" iyy="0.001" iyz="0.0" izz="0.001"/>
    </inertial>
  </link>
  <link name="LWristFlex_servo_lip">
    <visual>
      <geometry>
        <box size=".0528 .02 .002"/>
      </geometry>
      <origin rpy="0 0 0.001" xyz="0 0 0"/>
      <material name="black">
        <color rgba=".1 .1 1 1"/>
      </material>
    </visual>
    <collision>
      <geometry>
        <box size=".0528 .02 .002"/>
      </geometry>
      <origin rpy="0 0 0.001" xyz="0 0 0"/>
    </collision>
    <inertial>
      <mass value="0.001"/>
      <inertia ixx="0.001" ixy="0.0" ixz="0.0" iyy="0.001" iyz="0.0" izz="0.001"/>
    </inertial>
  </link>
  <link name="LWristFlex_servo_horn">
    <visual>
      <geometry>
        <cylinder length="0.001" radius="0.012"/>
      </geometry>
      <origin rpy="0 0 0" xyz="0 0 -.0005"/>
      <material name="white">
        <color rgba="1 1 1 1"/>
      </material>
    </visual>
    <collision>
      <geometry>
        <cylinder length="0.001" radius="0.012"/>
      </geometry>
      <origin rpy="0 0 0" xyz="0 0 -.0005"/>
    </collision>
    <inertial>
      <mass value="0.001"/>
      <inertia ixx="0.001" ixy="0.0" ixz="0.0" iyy="0.001" iyz="0.0" izz="0.001"/>
    </inertial>
  </link>
  <joint name="LWristFlex_servo_lip_to_body" type="fixed">
    <parent link="LWristFlex_servo_body"/>
    <child link="LWristFlex_servo_lip"/>
    <origin xyz="0.0161 0 0"/>
  </joint>
  <joint name="LWristFlex" type="revolute">
    <axis xyz="0 0 1"/>
    <limit effort="1000.0" lower="-1.5708" upper="1.5708" velocity="0.5"/>
    <parent link="LWristFlex_servo_horn"/>
    <child link="LWristFlex_servo_body"/>
    <origin rpy="0 0 0" xyz="0.0 0 -0.0161"/>
  </joint>
  <joint name="lwristflex_to_lforearm3" type="fixed">
    <parent link="lforearm3"/>
    <child link="LWristFlex_servo_horn"/>
    <origin rpy="0 1.5708 0" xyz="0.0246 0 -0.0286"/>
  </joint>
  <link name="lforearm4">
    <visual>
      <geometry>
        <mesh filename="package://george/meshes/multi-purp-simple.dae" scale="1 1 1"/>
      </geometry>
      <origin rpy="0 3.1416 0" xyz="0.0161 -0.0142 -0.0144"/>
      <material name="blue">
        <color rgba="0 0 .8 1"/>
      </material>
    </visual>
    <collision>
      <geometry>
        <box size=".005 .005 .005"/>
        <!--  mesh filename="package://george/meshes/multi-purp-simple.dae" scale="1 1 1"/-->
      </geometry>
      <origin rpy="0 3.1416 0" xyz="0.0161 -0.0142 -0.0144"/>
    </collision>
    <inertial>
      <mass value="0.001"/>
      <inertia ixx="0.001" ixy="0.0" ixz="0.0" iyy="0.001" iyz="0.0" izz="0.001"/>
    </inertial>
  </link>
  <joint name="lwristflex_to_lforearm4" type="fixed">
    <parent link="LWristFlex_servo_body"/>
    <child link="lforearm4"/>
    <origin rpy="0 0 0" xyz="0 0 0"/>
  </joint>
  <link name="lforearm5">
    <visual>
      <geometry>
        <mesh filename="package://george/meshes/lconnector-simple.dae" scale="1 1 1"/>
      </geometry>
      <origin rpy="0 0 0" xyz="0 0 0"/>
      <material name="blue">
        <color rgba="0 0 .8 1"/>
      </material>
    </visual>
    <collision>
      <geometry>
        <box size=".005 .005 .005"/>
        <!--  mesh filename="package://george/meshes/lconnector-simple.dae" scale="1 1 1"/-->
      </geometry>
      <origin rpy="0 0 0" xyz="0 0 0"/>
    </collision>
    <inertial>
      <mass value="0.001"/>
      <inertia ixx="0.001" ixy="0.0" ixz="0.0" iyy="0.001" iyz="0.0" izz="0.001"/>
    </inertial>
  </link>
  <joint name="lforearm4_to_lforearm5" type="fixed">
    <parent link="lforearm4"/>
    <child link="lforearm5"/>
    <origin rpy="0 0 0" xyz="0.0244 -0.0121 -0.008"/>
  </joint>
  <link name="ltube">
    <visual>
      <geometry>
        <cylinder length="0.079" radius="0.006"/>
      </geometry>
      <origin rpy="0 1.5708 0" xyz="0.0395 0 0"/>
      <material name="white">
        <color rgba="1 1 1 1"/>
      </material>
    </visual>
    <collision>
      <geometry>
        <cylinder length="0.079" radius="0.006"/>
      </geometry>
      <origin rpy="0 1.5708 0" xyz="0.0395 0 0"/>
    </collision>
    <inertial>
      <mass value="0.001"/>
      <inertia ixx="0.001" ixy="0.0" ixz="0.0" iyy="0.001" iyz="0.0" izz="0.001"/>
    </inertial>
  </link>
  <joint name="lforearm5_to_ltube" type="fixed">
    <parent link="lforearm5"/>
    <child link="ltube"/>
    <origin rpy="0 0 0" xyz="0.0227 0.013 0"/>
  </joint>
  <link name="ltip1">
    <visual>
      <geometry>
        <box size=".005 .005 .005"/>
      </geometry>
      <origin rpy="0 0 0" xyz="0 0 0"/>
      <material name="blue">
        <color rgba=".1 .1 1 1"/>
      </material>
    </visual>
  </link>
  <joint name="ltip1_to_ltube" type="revolute">
    <axis xyz="0 0 1"/>
    <limit effort="1000.0" lower="-1.5708" upper="1.5708" velocity="0.5"/>
    <parent link="ltube"/>
    <child link="ltip1"/>
    <origin rpy="0 0 0" xyz="0.070 0 0"/>
  </joint>
  <link name="ltip2">
    <visual>
      <geometry>
        <box size=".005 .005 .005"/>
      </geometry>
      <origin rpy="0 0 0" xyz="0 0 0"/>
      <material name="red">
        <color rgba="1 .1 .1 1"/>
      </material>
    </visual>
  </link>
  <joint name="ltip1_to_ltip2" type="revolute">
    <axis xyz="0 1 0"/>
    <limit effort="1000.0" lower="-1.5708" upper="1.5708" velocity="0.5"/>
    <parent link="ltip1"/>
    <child link="ltip2"/>
    <origin rpy="0 0 0" xyz="0.001 0 0"/>
  </joint>
  <link name="ltip3">
    <visual>
      <geometry>
        <box size=".005 .005 .005"/>
      </geometry>
      <origin rpy="0 0 0" xyz="0 0 0"/>
      <material name="green">
        <color rgba=".1 1 .1 1"/>
      </material>
    </visual>
  </link>
  <joint name="ltip2_to_ltip3" type="revolute">
    <axis xyz="1 0 0"/>
    <limit effort="1000.0" lower="-1.5708" upper="1.5708" velocity="0.5"/>
    <parent link="ltip2"/>
    <child link="ltip3"/>
    <origin rpy="0 0 0" xyz="0.001 0 0"/>
  </joint>
  <!-- *********************************************************** -->
  <!-- ***** Right Arm  ******************************************* -->
  <!-- *********************************************************** -->
  <link name="RShoulder_servo_body">
    <visual>
      <geometry>
        <box size=".040 .02 .0365"/>
      </geometry>
      <origin rpy="0 0 0" xyz="0 0 -0.00825"/>
      <material name="black">
        <color rgba=".1 .1 1 1"/>
      </material>
    </visual>
    <collision>
      <geometry>
        <box size=".040 .02 .0365"/>
      </geometry>
      <origin rpy="0 0 0" xyz="0 0 -0.00825"/>
    </collision>
    <inertial>
      <mass value="0.055"/>
      <inertia ixx="0.001" ixy="0.0" ixz="0.0" iyy="0.001" iyz="0.0" izz="0.001"/>
    </inertial>
  </link>
  <link name="RShoulder_servo_lip">
    <visual>
      <geometry>
        <box size=".0528 .02 .002"/>
      </geometry>
      <origin rpy="0 0 0.001" xyz="0 0 0"/>
      <material name="black">
        <color rgba=".1 .1 1 1"/>
      </material>
    </visual>
    <collision>
      <geometry>
        <box size=".0528 .02 .002"/>
      </geometry>
      <origin rpy="0 0 0.001" xyz="0 0 0"/>
    </collision>
    <inertial>
      <mass value="0.001"/>
      <inertia ixx="0.001" ixy="0.0" ixz="0.0" iyy="0.001" iyz="0.0" izz="0.001"/>
    </inertial>
  </link>
  <link name="RShoulder_servo_horn">
    <visual>
      <geometry>
        <cylinder length="0.001" radius="0.012"/>
      </geometry>
      <origin rpy="0 0 0" xyz="0 0 -.0005"/>
      <material name="white">
        <color rgba="1 1 1 1"/>
      </material>
    </visual>
    <collision>
      <geometry>
        <cylinder length="0.001" radius="0.012"/>
      </geometry>
      <origin rpy="0 0 0" xyz="0 0 -.0005"/>
    </collision>
    <inertial>
      <mass value="0.001"/>
      <inertia ixx="0.001" ixy="0.0" ixz="0.0" iyy="0.001" iyz="0.0" izz="0.001"/>
    </inertial>
  </link>
  <joint name="RShoulder_servo_lip_to_body" type="fixed">
    <parent link="RShoulder_servo_body"/>
    <child link="RShoulder_servo_lip"/>
    <origin xyz="0 0 0"/>
  </joint>
  <joint name="RShoulder" type="revolute">
    <axis xyz="0 0 -1"/>
    <limit effort="1000.0" lower="-1.5708" upper="1.5708" velocity="0.5"/>
    <parent link="RShoulder_servo_body"/>
    <child link="RShoulder_servo_horn"/>
    <origin rpy="0 0 0" xyz=".01 0 0.0161"/>
  </joint>
  <joint name="torso_to_rshoulder" type="fixed">
    <parent link="base_link"/>
    <child link="RShoulder_servo_body"/>
    <origin rpy="1.5708 0 -1.5708" xyz="-0.0380 0.023175 0.071438"/>
  </joint>
  <link name="rshoulder1">
    <visual>
      <geometry>
        <mesh filename="package://george/meshes/offset-c-simple.dae" scale="1 1 1"/>
      </geometry>
      <origin rpy="1.5708 0 0" xyz="0 0 0"/>
      <material name="blue">
        <color rgba="0 0 .8 1"/>
      </material>
    </visual>
    <collision>
      <geometry>
        <box size=".005 .005 .005"/>
        <!-- mesh filename="package://george/meshes/offset-c-simple.dae" scale="1 1 1"/-->
      </geometry>
      <origin rpy="1.5708 0 0" xyz="0 0 0"/>
    </collision>
    <inertial>
      <mass value="0.001"/>
      <inertia ixx="0.001" ixy="0.0" ixz="0.0" iyy="0.001" iyz="0.0" izz="0.001"/>
    </inertial>
  </link>
  <joint name="rshoulder1_to_rshoulder" type="fixed">
    <parent link="RShoulder_servo_horn"/>
    <child link="rshoulder1"/>
    <origin rpy="0 0 1.5708" xyz="0 0 0"/>
  </joint>
  <link name="RElbow_servo_body">
    <visual>
      <geometry>
        <box size=".040 .02 .0365"/>
      </geometry>
      <origin rpy="0 0 0" xyz="0.0161 0 -0.00825"/>
      <material name="black">
        <color rgba=".1 .1 1 1"/>
      </material>
    </visual>
    <collision>
      <geometry>
        <box size=".040 .02 .0365"/>
      </geometry>
      <origin rpy="0 0 0" xyz="0.0161 0 -0.00825"/>
    </collision>
    <inertial>
      <mass value="0.055"/>
      <inertia ixx="0.001" ixy="0.0" ixz="0.0" iyy="0.001" iyz="0.0" izz="0.001"/>
    </inertial>
  </link>
  <link name="RElbow_servo_lip">
    <visual>
      <geometry>
        <box size=".0528 .02 .002"/>
      </geometry>
      <origin rpy="0 0 0.001" xyz="0 0 0"/>
      <material name="black">
        <color rgba=".1 .1 1 1"/>
      </material>
    </visual>
    <collision>
      <geometry>
        <box size=".0528 .02 .002"/>
      </geometry>
      <origin rpy="0 0 0.001" xyz="0 0 0"/>
    </collision>
    <inertial>
      <mass value="0.001"/>
      <inertia ixx="0.001" ixy="0.0" ixz="0.0" iyy="0.001" iyz="0.0" izz="0.001"/>
    </inertial>
  </link>
  <link name="RElbow_servo_horn">
    <visual>
      <geometry>
        <cylinder length="0.001" radius="0.012"/>
      </geometry>
      <origin rpy="0 0 0" xyz="0 0 -.0005"/>
      <material name="white">
        <color rgba="1 1 1 1"/>
      </material>
    </visual>
    <collision>
      <geometry>
        <cylinder length="0.001" radius="0.012"/>
      </geometry>
      <origin rpy="0 0 0" xyz="0 0 -.0005"/>
    </collision>
    <inertial>
      <mass value="0.001"/>
      <inertia ixx="0.001" ixy="0.0" ixz="0.0" iyy="0.001" iyz="0.0" izz="0.001"/>
    </inertial>
  </link>
  <joint name="RElbow_servo_lip_to_body" type="fixed">
    <parent link="RElbow_servo_body"/>
    <child link="RElbow_servo_lip"/>
    <origin xyz="0.0161 0 0"/>
  </joint>
  <joint name="RElbow" type="revolute">
    <axis xyz="0 0 1"/>
    <limit effort="1000.0" lower="-1.5708" upper="1.5708" velocity="0.5"/>
    <parent link="RElbow_servo_horn"/>
    <child link="RElbow_servo_body"/>
    <origin rpy="0 0 0" xyz="0.0 0 -0.0161"/>
  </joint>
  <joint name="relbow_to_shoulder1" type="fixed">
    <parent link="rshoulder1"/>
    <child link="RElbow_servo_horn"/>
    <origin rpy="0 -1.5708 0" xyz="-0.0246 0.0187 0.027"/>
  </joint>
  <link name="rforearm1">
    <visual>
      <geometry>
        <mesh filename="package://george/meshes/multi-purp-simple.dae" scale="1 1 1"/>
      </geometry>
      <origin rpy="0 3.1416 0" xyz="0.0161 -0.0142 -0.0144"/>
      <material name="blue">
        <color rgba="0 0 .8 1"/>
      </material>
    </visual>
    <collision>
      <geometry>
        <box size=".005 .005 .005"/>
        <!--  mesh filename="package://george/meshes/multi-purp-simple.dae" scale="1 1 1"/-->
      </geometry>
      <origin rpy="0 3.1416 0" xyz="0.0161 -0.0142 -0.0144"/>
    </collision>
    <inertial>
      <mass value="0.001"/>
      <inertia ixx="0.001" ixy="0.0" ixz="0.0" iyy="0.001" iyz="0.0" izz="0.001"/>
    </inertial>
  </link>
  <joint name="rforearm1_to_relbow" type="fixed">
    <parent link="RElbow_servo_body"/>
    <child link="rforearm1"/>
    <origin rpy="3.1416 3.1416 0" xyz="0.0322 0 0"/>
  </joint>
  <link name="rforearm2">
    <visual>
      <geometry>
        <mesh filename="package://george/meshes/multi-purp-simple.dae" scale="1 1 1"/>
      </geometry>
      <origin rpy="-1.5708 0 1.5708" xyz="0 0 0"/>
      <material name="blue">
        <color rgba="0 0 .8 1"/>
      </material>
    </visual>
    <collision>
      <geometry>
        <box size=".005 .005 .005"/>
        <!--  mesh filename="package://george/meshes/multi-purp-simple.dae" scale="1 1 1"/-->
      </geometry>
      <origin rpy="-1.5708 0 1.5708" xyz="0 0 0"/>
    </collision>
    <inertial>
      <mass value="0.001"/>
      <inertia ixx="0.001" ixy="0.0" ixz="0.0" iyy="0.001" iyz="0.0" izz="0.001"/>
    </inertial>
  </link>
  <joint name="rforearm2_to_rforearm1" type="fixed">
    <parent link="rforearm1"/>
    <child link="rforearm2"/>
    <origin rpy="-1.5708 3.1416 0" xyz="0.0024 -0.0142 -0.0163"/>
  </joint>
  <link name="RWristTwist_servo_body">
    <visual>
      <geometry>
        <box size=".040 .02 .0365"/>
      </geometry>
      <origin rpy="0 0 0" xyz="0 0 -0.00825"/>
      <material name="black">
        <color rgba=".1 .1 1 1"/>
      </material>
    </visual>
    <collision>
      <geometry>
        <box size=".040 .02 .0365"/>
      </geometry>
      <origin rpy="0 0 0" xyz="0 0 -0.00825"/>
    </collision>
    <inertial>
      <mass value="0.055"/>
      <inertia ixx="0.001" ixy="0.0" ixz="0.0" iyy="0.001" iyz="0.0" izz="0.001"/>
    </inertial>
  </link>
  <link name="RWristTwist_servo_lip">
    <visual>
      <geometry>
        <box size=".0528 .02 .002"/>
      </geometry>
      <origin rpy="0 0 0.001" xyz="0 0 0"/>
      <material name="black">
        <color rgba=".1 .1 1 1"/>
      </material>
    </visual>
    <collision>
      <geometry>
        <box size=".0528 .02 .002"/>
      </geometry>
      <origin rpy="0 0 0.001" xyz="0 0 0"/>
    </collision>
    <inertial>
      <mass value="0.001"/>
      <inertia ixx="0.001" ixy="0.0" ixz="0.0" iyy="0.001" iyz="0.0" izz="0.001"/>
    </inertial>
  </link>
  <link name="RWristTwist_servo_horn">
    <visual>
      <geometry>
        <cylinder length="0.001" radius="0.012"/>
      </geometry>
      <origin rpy="0 0 0" xyz="0 0 -.0005"/>
      <material name="white">
        <color rgba="1 1 1 1"/>
      </material>
    </visual>
    <collision>
      <geometry>
        <cylinder length="0.001" radius="0.012"/>
      </geometry>
      <origin rpy="0 0 0" xyz="0 0 -.0005"/>
    </collision>
    <inertial>
      <mass value="0.001"/>
      <inertia ixx="0.001" ixy="0.0" ixz="0.0" iyy="0.001" iyz="0.0" izz="0.001"/>
    </inertial>
  </link>
  <joint name="RWristTwist_servo_lip_to_body" type="fixed">
    <parent link="RWristTwist_servo_body"/>
    <child link="RWristTwist_servo_lip"/>
    <origin xyz="0 0 0"/>
  </joint>
  <joint name="RWristTwist" type="revolute">
    <axis xyz="0 0 -1"/>
    <limit effort="1000.0" lower="-1.5708" upper="1.5708" velocity="0.5"/>
    <parent link="RWristTwist_servo_body"/>
    <child link="RWristTwist_servo_horn"/>
    <origin rpy="0 0 0" xyz=".01 0 0.0161"/>
  </joint>
  <joint name="rwristtwist_to_rforearm2" type="fixed">
    <parent link="rforearm2"/>
    <child link="RWristTwist_servo_body"/>
    <origin rpy="1.5708 0 1.5708" xyz="0.0144 0 -0.0142"/>
  </joint>
  <link name="RHand_base">
    <visual>
      <geometry>
        <mesh filename="package://george/meshes/gripper-base.dae" scale="1 1 1"/>
      </geometry>
      <origin rpy="0 -1.5708 0" xyz="0 0 0"/>
      <material name="blue">
        <color rgba="0 0 .8 1"/>
      </material>
    </visual>
    <collision>
      <geometry>
        <box size=".005 .005 .005"/>
      </geometry>
    </collision>
    <inertial>
      <mass value="0.001"/>
      <inertia ixx="0.001" ixy="0.0" ixz="0.0" iyy="0.001" iyz="0.0" izz="0.001"/>
    </inertial>
  </link>
  <link name="RHand_lfinger">
    <visual>
      <geometry>
        <mesh filename="package://george/meshes/gripper-lfinger.dae" scale="1 1 1"/>
      </geometry>
      <origin rpy="0 0 0" xyz="0 0 0"/>
      <material name="blue">
        <color rgba="0 0 .8 1"/>
      </material>
    </visual>
    <collision>
      <geometry>
        <box size=".005 .005 .005"/>
      </geometry>
    </collision>
    <inertial>
      <mass value="0.001"/>
      <inertia ixx="0.001" ixy="0.0" ixz="0.0" iyy="0.001" iyz="0.0" izz="0.001"/>
    </inertial>
  </link>
  <joint name="RHand_lfinger_to_base" type="fixed">
    <axis xyz="0 1 0"/>
    <parent link="RHand_base"/>
    <child link="RHand_lfinger"/>
    <origin rpy="0 -1.5708 0" xyz="0 0 0"/>
    <limit effort="1000.0" lower="-0.005" upper="0.0137" velocity="0.5"/>
  </joint>
  <link name="RHand_rfinger">
    <visual>
      <geometry>
        <mesh filename="package://george/meshes/gripper-rfinger.dae" scale="1 1 1"/>
      </geometry>
      <origin rpy="0 0 0" xyz="0 0 0"/>
      <material name="blue">
        <color rgba="0 0 .8 1"/>
      </material>
    </visual>
    <collision>
      <geometry>
        <box size=".005 .005 .005"/>
      </geometry>
    </collision>
    <inertial>
      <mass value="0.001"/>
      <inertia ixx="0.001" ixy="0.0" ixz="0.0" iyy="0.001" iyz="0.0" izz="0.001"/>
    </inertial>
  </link>
  <joint name="RHand_rfinger_to_base" type="fixed">
    <!--joint name="${name}_rfinger_to_base" type="prismatic"-->
    <axis xyz="0 1 0"/>
    <parent link="RHand_base"/>
    <child link="RHand_rfinger"/>
    <origin rpy="0 -1.5708 0" xyz="0 0 0"/>
    <limit effort="1000.0" lower="-0.0137" upper="0.005" velocity="0.5"/>
  </joint>
  <link name="RHand_servo_body">
    <visual>
      <geometry>
        <box size=".040 .02 .0365"/>
      </geometry>
      <origin rpy="0 0 0" xyz="0 0 -0.00825"/>
      <material name="black">
        <color rgba=".1 .1 1 1"/>
      </material>
    </visual>
    <collision>
      <geometry>
        <box size=".040 .02 .0365"/>
      </geometry>
      <origin rpy="0 0 0" xyz="0 0 -0.00825"/>
    </collision>
    <inertial>
      <mass value="0.055"/>
      <inertia ixx="0.001" ixy="0.0" ixz="0.0" iyy="0.001" iyz="0.0" izz="0.001"/>
    </inertial>
  </link>
  <link name="RHand_servo_lip">
    <visual>
      <geometry>
        <box size=".0528 .02 .002"/>
      </geometry>
      <origin rpy="0 0 0.001" xyz="0 0 0"/>
      <material name="black">
        <color rgba=".1 .1 1 1"/>
      </material>
    </visual>
    <collision>
      <geometry>
        <box size=".0528 .02 .002"/>
      </geometry>
      <origin rpy="0 0 0.001" xyz="0 0 0"/>
    </collision>
    <inertial>
      <mass value="0.001"/>
      <inertia ixx="0.001" ixy="0.0" ixz="0.0" iyy="0.001" iyz="0.0" izz="0.001"/>
    </inertial>
  </link>
  <link name="RHand_servo_horn">
    <visual>
      <geometry>
        <cylinder length="0.001" radius="0.012"/>
      </geometry>
      <origin rpy="0 0 0" xyz="0 0 -.0005"/>
      <material name="white">
        <color rgba="1 1 1 1"/>
      </material>
    </visual>
    <collision>
      <geometry>
        <cylinder length="0.001" radius="0.012"/>
      </geometry>
      <origin rpy="0 0 0" xyz="0 0 -.0005"/>
    </collision>
    <inertial>
      <mass value="0.001"/>
      <inertia ixx="0.001" ixy="0.0" ixz="0.0" iyy="0.001" iyz="0.0" izz="0.001"/>
    </inertial>
  </link>
  <joint name="RHand_servo_lip_to_body" type="fixed">
    <parent link="RHand_servo_body"/>
    <child link="RHand_servo_lip"/>
    <origin xyz="0 0 0"/>
  </joint>
  <joint name="RHand" type="revolute">
    <axis xyz="0 0 -1"/>
    <limit effort="1000.0" lower="-1.5708" upper="1.5708" velocity="0.5"/>
    <parent link="RHand_servo_body"/>
    <child link="RHand_servo_horn"/>
    <origin rpy="0 0 0" xyz=".01 0 0.0161"/>
  </joint>
  <joint name="RHand_servo_to_base" type="fixed">
    <parent link="RHand_base"/>
    <child link="RHand_servo_body"/>
    <origin rpy="1.5708 0 -1.5708" xyz="0.0058 0.0095 0.01195"/>
  </joint>
  <joint name="gripper_to_wrist" type="fixed">
    <parent link="RWristTwist_servo_horn"/>
    <child link="RHand_base"/>
    <origin rpy="0 0 0" xyz="0 0 0"/>
  </joint>
  <link name="rtip1">
    <visual>
      <geometry>
        <box size=".005 .005 .005"/>
      </geometry>
      <origin rpy="0 0 0" xyz="0 0 0"/>
      <material name="blue">
        <color rgba=".1 .1 1 1"/>
      </material>
    </visual>
  </link>
  <joint name="rtip1" type="fixed">
    <axis xyz="0 0 1"/>
    <limit effort="1000.0" lower="-1.5708" upper="1.5708" velocity="0.5"/>
    <parent link="RHand_base"/>
    <child link="rtip1"/>
    <origin rpy="0 1.5708 0" xyz="0 0 0.070"/>
  </joint>
  <link name="rtip2">
    <visual>
      <geometry>
        <box size=".005 .005 .005"/>
      </geometry>
      <origin rpy="0 0 0" xyz="0 0 0"/>
      <material name="red">
        <color rgba="1 .1 .1 1"/>
      </material>
    </visual>
  </link>
  <joint name="rtip1_to_rtip2" type="revolute">
    <axis xyz="0 1 0"/>
    <limit effort="1000.0" lower="-1.5708" upper="1.5708" velocity="0.5"/>
    <parent link="rtip1"/>
    <child link="rtip2"/>
    <origin rpy="0 0 0" xyz="-0.001 0 0"/>
  </joint>
  <link name="rtip3">
    <visual>
      <geometry>
        <box size=".005 .005 .005"/>
      </geometry>
      <origin rpy="0 0 0" xyz="0 0 0"/>
      <material name="green">
        <color rgba=".1 1 .1 1"/>
      </material>
    </visual>
  </link>
  <joint name="rtip2_to_rtip3" type="revolute">
    <axis xyz="1 0 0"/>
    <limit effort="1000.0" lower="-1.5708" upper="1.5708" velocity="0.5"/>
    <parent link="rtip2"/>
    <child link="rtip3"/>
    <origin rpy="0 0 0" xyz="-0.001 0 0"/>
  </joint>
  <!-- *********************************************************** -->
  <!-- ***** head      ******************************************* -->
  <!-- *********************************************************** -->
  <link name="Head_servo_body">
    <visual>
      <geometry>
        <box size=".040 .02 .0365"/>
      </geometry>
      <origin rpy="0 0 0" xyz="0 0 -0.00825"/>
      <material name="black">
        <color rgba=".1 .1 1 1"/>
      </material>
    </visual>
    <collision>
      <geometry>
        <box size=".040 .02 .0365"/>
      </geometry>
      <origin rpy="0 0 0" xyz="0 0 -0.00825"/>
    </collision>
    <inertial>
      <mass value="0.055"/>
      <inertia ixx="0.001" ixy="0.0" ixz="0.0" iyy="0.001" iyz="0.0" izz="0.001"/>
    </inertial>
  </link>
  <link name="Head_servo_lip">
    <visual>
      <geometry>
        <box size=".0528 .02 .002"/>
      </geometry>
      <origin rpy="0 0 0.001" xyz="0 0 0"/>
      <material name="black">
        <color rgba=".1 .1 1 1"/>
      </material>
    </visual>
    <collision>
      <geometry>
        <box size=".0528 .02 .002"/>
      </geometry>
      <origin rpy="0 0 0.001" xyz="0 0 0"/>
    </collision>
    <inertial>
      <mass value="0.001"/>
      <inertia ixx="0.001" ixy="0.0" ixz="0.0" iyy="0.001" iyz="0.0" izz="0.001"/>
    </inertial>
  </link>
  <link name="Head_servo_horn">
    <visual>
      <geometry>
        <cylinder length="0.001" radius="0.012"/>
      </geometry>
      <origin rpy="0 0 0" xyz="0 0 -.0005"/>
      <material name="white">
        <color rgba="1 1 1 1"/>
      </material>
    </visual>
    <collision>
      <geometry>
        <cylinder length="0.001" radius="0.012"/>
      </geometry>
      <origin rpy="0 0 0" xyz="0 0 -.0005"/>
    </collision>
    <inertial>
      <mass value="0.001"/>
      <inertia ixx="0.001" ixy="0.0" ixz="0.0" iyy="0.001" iyz="0.0" izz="0.001"/>
    </inertial>
  </link>
  <joint name="Head_servo_lip_to_body" type="fixed">
    <parent link="Head_servo_body"/>
    <child link="Head_servo_lip"/>
    <origin xyz="0 0 0"/>
  </joint>
  <joint name="Head" type="revolute">
    <axis xyz="0 0 -1"/>
    <limit effort="1000.0" lower="-1.5708" upper="1.5708" velocity="0.5"/>
    <parent link="Head_servo_body"/>
    <child link="Head_servo_horn"/>
    <origin rpy="0 0 0" xyz=".01 0 0.0161"/>
  </joint>
  <joint name="torso_to_head" type="fixed">
    <parent link="base_link"/>
    <child link="Head_servo_body"/>
    <origin rpy="0 0 -1.5708" xyz="0 0.023175 0.087313"/>
  </joint>
  <!--   ['RWaist', 'RHip', 'RKnee', 'RAnkleBend', 'RAnkleRotate', 'RAnkleTilt', 
        'LWaist', 'LHip', 'LKnee', 'LAnkleBend', 'LAnkleRotate', 'LAnkleTilt', 
        'LShoulder', 'LElbow', 'LWristTwist', 'LWristFlex', 
        'RShoulder', 'RElbow', 'RWristTwist', 'RHand', 'Head']
-->
  <!-- *********************************************************** -->
  <!-- *** Gazebo sim stuff ************************************** -->
  <!-- *********************************************************** -->
  <transmission name="tran0">
    <type>transmission_interface/SimpleTransmission</type>
    <joint name="RWaist"/>
    <actuator name="motor0">
      <hardwareInterface>EffortJointInterface</hardwareInterface>
      <mechanicalReduction>1</mechanicalReduction>
    </actuator>
  </transmission>
  <transmission name="tran1">
    <type>transmission_interface/SimpleTransmission</type>
    <joint name="RHip"/>
    <actuator name="motor1">
      <hardwareInterface>EffortJointInterface</hardwareInterface>
      <mechanicalReduction>1</mechanicalReduction>
    </actuator>
  </transmission>
  <transmission name="tran2">
    <type>transmission_interface/SimpleTransmission</type>
    <joint name="RKnee"/>
    <actuator name="motor2">
      <hardwareInterface>EffortJointInterface</hardwareInterface>
      <mechanicalReduction>1</mechanicalReduction>
    </actuator>
  </transmission>
  <transmission name="tran3">
    <type>transmission_interface/SimpleTransmission</type>
    <joint name="RAnkleBend"/>
    <actuator name="motor3">
      <hardwareInterface>EffortJointInterface</hardwareInterface>
      <mechanicalReduction>1</mechanicalReduction>
    </actuator>
  </transmission>
  <transmission name="tran4">
    <type>transmission_interface/SimpleTransmission</type>
    <joint name="RAnkleRotate"/>
    <actuator name="motor4">
      <hardwareInterface>EffortJointInterface</hardwareInterface>
      <mechanicalReduction>1</mechanicalReduction>
    </actuator>
  </transmission>
  <transmission name="tran5">
    <type>transmission_interface/SimpleTransmission</type>
    <joint name="RAnkleTilt"/>
    <actuator name="motor5">
      <hardwareInterface>EffortJointInterface</hardwareInterface>
      <mechanicalReduction>1</mechanicalReduction>
    </actuator>
  </transmission>
  <transmission name="tran6">
    <type>transmission_interface/SimpleTransmission</type>
    <joint name="LWaist"/>
    <actuator name="motor6">
      <hardwareInterface>EffortJointInterface</hardwareInterface>
      <mechanicalReduction>1</mechanicalReduction>
    </actuator>
  </transmission>
  <transmission name="tran7">
    <type>transmission_interface/SimpleTransmission</type>
    <joint name="LHip"/>
    <actuator name="motor7">
      <hardwareInterface>EffortJointInterface</hardwareInterface>
      <mechanicalReduction>1</mechanicalReduction>
    </actuator>
  </transmission>
  <transmission name="tran8">
    <type>transmission_interface/SimpleTransmission</type>
    <joint name="LKnee"/>
    <actuator name="motor8">
      <hardwareInterface>EffortJointInterface</hardwareInterface>
      <mechanicalReduction>1</mechanicalReduction>
    </actuator>
  </transmission>
  <transmission name="tran9">
    <type>transmission_interface/SimpleTransmission</type>
    <joint name="LAnkleBend"/>
    <actuator name="motor9">
      <hardwareInterface>EffortJointInterface</hardwareInterface>
      <mechanicalReduction>1</mechanicalReduction>
    </actuator>
  </transmission>
  <transmission name="tran10">
    <type>transmission_interface/SimpleTransmission</type>
    <joint name="LAnkleRotate"/>
    <actuator name="motor10">
      <hardwareInterface>EffortJointInterface</hardwareInterface>
      <mechanicalReduction>1</mechanicalReduction>
    </actuator>
  </transmission>
  <transmission name="tran11">
    <type>transmission_interface/SimpleTransmission</type>
    <joint name="LAnkleTilt"/>
    <actuator name="motor11">
      <hardwareInterface>EffortJointInterface</hardwareInterface>
      <mechanicalReduction>1</mechanicalReduction>
    </actuator>
  </transmission>
  <transmission name="tran12">
    <type>transmission_interface/SimpleTransmission</type>
    <joint name="LShoulder"/>
    <actuator name="motor12">
      <hardwareInterface>EffortJointInterface</hardwareInterface>
      <mechanicalReduction>1</mechanicalReduction>
    </actuator>
  </transmission>
  <transmission name="tran13">
    <type>transmission_interface/SimpleTransmission</type>
    <joint name="LElbow"/>
    <actuator name="motor13">
      <hardwareInterface>EffortJointInterface</hardwareInterface>
      <mechanicalReduction>1</mechanicalReduction>
    </actuator>
  </transmission>
  <transmission name="tran14">
    <type>transmission_interface/SimpleTransmission</type>
    <joint name="LWristTwist"/>
    <actuator name="motor14">
      <hardwareInterface>EffortJointInterface</hardwareInterface>
      <mechanicalReduction>1</mechanicalReduction>
    </actuator>
  </transmission>
  <transmission name="tran15">
    <type>transmission_interface/SimpleTransmission</type>
    <joint name="LWristFlex"/>
    <actuator name="motor15">
      <hardwareInterface>EffortJointInterface</hardwareInterface>
      <mechanicalReduction>1</mechanicalReduction>
    </actuator>
  </transmission>
  <transmission name="tran16">
    <type>transmission_interface/SimpleTransmission</type>
    <joint name="RShoulder"/>
    <actuator name="motor16">
      <hardwareInterface>EffortJointInterface</hardwareInterface>
      <mechanicalReduction>1</mechanicalReduction>
    </actuator>
  </transmission>
  <transmission name="tran17">
    <type>transmission_interface/SimpleTransmission</type>
    <joint name="RElbow"/>
    <actuator name="motor17">
      <hardwareInterface>EffortJointInterface</hardwareInterface>
      <mechanicalReduction>1</mechanicalReduction>
    </actuator>
  </transmission>
  <transmission name="tran18">
    <type>transmission_interface/SimpleTransmission</type>
    <joint name="RWristTwist"/>
    <actuator name="motor18">
      <hardwareInterface>EffortJointInterface</hardwareInterface>
      <mechanicalReduction>1</mechanicalReduction>
    </actuator>
  </transmission>
  <!--  transmission name="tran19">
    <type>transmission_interface/SimpleTransmission</type>
    <joint name="RHand" />
    <actuator name="motor19">
      <hardwareInterface>EffortJointInterface</hardwareInterface>
      <mechanicalReduction>1</mechanicalReduction>
    </actuator>
  </transmission-->
  <transmission name="tran20">
    <type>transmission_interface/SimpleTransmission</type>
    <joint name="Head"/>
    <actuator name="motor20">
      <hardwareInterface>EffortJointInterface</hardwareInterface>
      <mechanicalReduction>1</mechanicalReduction>
    </actuator>
  </transmission>
</robot>
